Workbook

Sheet 22.5월
B2: 자 금 일 보
J3: 계정과목 | K3: 설명
B4: ※ 자금현황 | G4: 44804 | J4: 복리후생비 | K4: 회식, 식대
B5: 구 분 | C5: 단위 | D5: 전월잔액 | E5: 수 입 | F5: 지 출 | G5: 기준일 기준 잔액 | J5: 여비교통비 | K5: 출장, 대중교통, 대리운전
B6: 신한 #672 | C6: KRW | E6: =sumif(B20:B129,B6,E20:E129) -> 50872576 | F6: =sumif(B20:B172,B6,F20:F172) -> 40470136 | G6: =D6+E6-F6 -> 10402440 | J6: 비품 | K6: 가구, 가전등 개당 단가 150만원이 넘는 용품
B7: WISE USD | C7: USD | E7: =sumif(B20:B172,B7,E20:E129) -> 0 | F7: =sumif(B20:B172,B7,F20:F172) -> 0 | G7: =D7+E7-F7 -> 0 | J7: 소모품비 | K7: 비품(150만원)으로 잡기에는 금액이 작은 비품
B8: WISE SGD | C8: SGD | E8: =sumif(B20:B129,B8,E20:E172) -> 0 | F8: =sumif(B20:B172,B8,F20:F172) -> 0 | G8: =D8+E8-F8 -> 0 | J8: 사무용품비 | K8: 비품, 소모품비를 제외한 업무용 사무용품 구입
B9: WISE KRW | C9: KRW | E9: =sumif(B20:B129,B9,E20:E129) -> 0 | F9: =sumif(B20:B172,B9,F20:F172) -> 0 | G9: =D9+E9-F9 -> 0 | J9: 통신비 | K9: 등기, 퀵 사용비
J10: 접대비 | K10: 외부 미팅
J11: 세금과공과 | K11: 세금 납부시
J12: 지급수수료 | K12: sms 수수료, 송금 수수료, 일반적으로 발생되는 모든 비용
B13: KRW 합 계 | J13: 미수금 | K13: 돌려 받을 예정인 금액 (ex. 부가세 환급금)
B14: USD 합 계 | J14: 용역비 | K14: 외주용역비
J15: 급여 | K15: 직원 급여
B18: ※ 세부내역
B19: 구 분 | C19: 날 짜 | D19: 은 행 적 요 | E19: 수입 | F19: 지출 | G19: 상세메모 | H19: 계정과목
B20: =B6 -> 신한 #672 | C20: 2022.05.25 12:29:55 | D20: 신규 | E20: 0 | F20: 0
B21: =B6 -> 신한 #672 | C21: 2022.05.25 12:51:34 | D21: 대체 | E21: 50000000 | F21: 0 | G21: 주식(사채)납입
B22: =B6 -> 신한 #672 | C22: 2022.05.25 12:55:39 | D22: 대체 | E22: 872557 | F22: 0
B23: =B6 -> 신한 #672 | C23: 2022.05.25 12:56:47 | D23: 대체 | E23: 19 | F23: 0
B24: =B6 -> 신한 #672 | C24: 2022.05.25 14:48:30 | D24: BZ뱅크 | E24: 0 | F24: 4400 | G24: 공동인증수수료 | H24: 지급수수료
B25: =B6 -> 신한 #672 | C25: 2022.05.25 15:22:16 | D25: BZ뱅크 | E25: 0 | F25: 6447167 | G25: 김석준05월급여 | H25: 급여
B26: =B6 -> 신한 #672 | C26: 2022.05.25 15:22:17 | D26: BZ뱅크 | E26: 0 | F26: 6447167 | G26: 전준영05월급여 | H26: 급여
B27: =B6 -> 신한 #672 | C27: 2022.05.25 15:22:17 | D27: BZ뱅크 | E27: 0 | F27: 6447167 | G27: 최고은05월급여 | H27: 급여
B28: =B6 -> 신한 #672 | C28: 2022.05.25 15:22:18 | D28: BZ뱅크 | E28: 0 | F28: 6446667 | G28: 강진석05월급여 | H28: 급여
B29: =B6 -> 신한 #672 | C29: 2022.05.25 15:22:18 | D29: BZ뱅크 | E29: 0 | F29: 2015103 | G29: 고유빈05월급여 | H29: 급여
B30: =B6 -> 신한 #672 | C30: 2022.05.25 15:22:19 | D30: BZ뱅크 | E30: 0 | F30: 1684965 | G30: 이태호05월급여 | H30: 급여
B31: =B6 -> 신한 #672 | C31: 2022.05.25 17:03:15 | D31: BZ뱅크 | E31: 0 | F31: 7832500 | G31: 개발자맥북구매 | H31: 비품
B32: =B6 -> 신한 #672 | C32: 2022.05.31 15:03:54 | D32: BZ뱅크 | E32: 0 | F32: 3089200 | G32: 바트5월개인 | H32: 여비교통비
B33: =B6 -> 신한 #672 | C33: 2022.05.31 15:08:07 | D33: BZ뱅크 | E33: 0 | F33: 55800 | G33: 진04월개인 | H33: 여비교통비

Sheet 22.6월
B2: 자 금 일 보
J3: 계정과목 | K3: 설명
B4: ※ 자금현황 | G4: 44804 | J4: 복리후생비 | K4: 회식, 식대
B5: 구 분 | C5: 단위 | D5: 전월잔액 | E5: 수 입 | F5: 지 출 | G5: 기준일 기준 잔액 | J5: 여비교통비 | K5: 출장, 대중교통, 대리운전
B6: 신한 #672 | C6: KRW | D6: 10402440 | E6: =sumif(B20:B129,B6,E20:E129) -> 128447937 | F6: =sumif(B20:B172,B6,F20:F172) -> 47664363 | G6: =D6+E6-F6 -> 91186014 | J6: 비품 | K6: 가구, 가전등 개당 단가 150만원이 넘는 용품
B7: WISE USD | C7: USD | E7: =sumif(B20:B172,B7,E20:E129) -> 0 | F7: =sumif(B20:B172,B7,F20:F172) -> 0 | G7: =D7+E7-F7 -> 0 | J7: 소모품비 | K7: 비품(150만원)으로 잡기에는 금액이 작은 비품
B8: WISE SGD | C8: SGD | E8: =sumif(B20:B129,B8,E20:E172) -> 0 | F8: =sumif(B20:B172,B8,F20:F172) -> 0 | G8: =D8+E8-F8 -> 0 | J8: 사무용품비 | K8: 비품, 소모품비를 제외한 업무용 사무용품 구입
B9: WISE KRW | C9: KRW | E9: =sumif(B20:B129,B9,E20:E129) -> 0 | F9: =sumif(B20:B172,B9,F20:F172) -> 0 | G9: =D9+E9-F9 -> 0 | J9: 통신비 | K9: 등기, 퀵 사용비
J10: 접대비 | K10: 외부 미팅
J11: 세금과공과 | K11: 세금 납부시
J12: 지급수수료 | K12: sms 수수료, 송금 수수료, 일반적으로 발생되는 모든 비용
B13: KRW 합 계 | J13: 미수금 | K13: 돌려 받을 예정인 금액 (ex. 부가세 환급금)
B14: USD 합 계 | J14: 용역비 | K14: 외주용역비
J15: 급여 | K15: 직원 급여
J16: 이자수익 | K16: 은행이자
J17: 서비스용역매출 | K17: 싱가폴 -> 한국 지사 송금
B18: ※ 세부내역
B19: 구 분 | C19: 날 짜 | D19: 은 행 적 요 | E19: 수입 | F19: 지출 | G19: 상세메모 | H19: 계정과목
B20: =B6 -> 신한 #672 | C20: 2022.06.07 13:53:34 | D20: BZ뱅크 | E20: 0 | F20: 177040 | G20: 05월지방세 | H20: 세금과공과
B21: =B6 -> 신한 #672 | C21: 2022.06.07 13:59:33 | D21: BZ뱅크 | E21: 0 | F21: 1770630 | G21: 05사업소득세 | H21: 세금과공과
B22: =B6 -> 신한 #672 | C22: 2022.06.18 02:11:20 | D22: 이자 | E22: 676 | F22: 0 | G22: 05.25~06.17 | H22: 이자수익
B23: =B6 -> 신한 #672 | C23: 2022.06.21 15:28:50 | D23: BZ뱅크 | E23: 0 | F23: 3916500 | G23: 개발자맥북구매 | H23: 비품
B24: =B6 -> 신한 #672 | C24: 2022.06.22 00:02:06 | D24: 신한체 | E24: 0 | F24: 30000 | G24: 네꼬 | H24: 접대비
B25: =B6 -> 신한 #672 | C25: 2022.06.22 11:00:13 | D25: 타행PC | E25: 128439661 | F25: 0 | G25: Zero X And | H25: 서비스용역매출
B26: =B6 -> 신한 #672 | C26: 2022.06.22 11:57:20 | D26: 신한체 | E26: 0 | F26: 5800 | G26: 로카모빌리티택 | H26: 여비교통비
B27: =B6 -> 신한 #672 | C27: 2022.06.22 16:53:06 | D27: 신한체 | E27: 0 | F27: 10700 | G27: 뚜레쥬르 역삼 | H27: 접대비
B28: =B6 -> 신한 #672 | C28: 2022.06.22 18:44:42 | D28: 신한체 | E28: 0 | F28: 7600 | G28: 카카오택시(선 | H28: 여비교통비
B29: =B6 -> 신한 #672 | C29: 2022.06.22 18:44:43 | D29: 신한체 | E29: 7600 | F29: 0 | G29: 카카오택시(선 | H29: 여비교통비
B30: =B6 -> 신한 #672 | C30: 2022.06.22 18:59:26 | D30: 신한체 | E30: 0 | F30: 3000 | G30: 카카오페이(택 | H30: 여비교통비
B31: =B6 -> 신한 #672 | C31: 2022.06.22 18:59:27 | D31: 신한체 | E31: 0 | F31: 4600 | G31: 카카오페이(택 | H31: 여비교통비
B32: =B6 -> 신한 #672 | C32: 2022.06.22 23:32:05 | D32: 신한체 | E32: 0 | F32: 300000 | G32: 스커트 | H32: 접대비
B33: =B6 -> 신한 #672 | C33: 2022.06.23 03:07:44 | D33: 신한체 | E33: 0 | F33: 22600 | G33: 티머니 법인택 | H33: 여비교통비
B34: =B6 -> 신한 #672 | C34: 2022.06.24 14:14:23 | D34: 신한체 | E34: 0 | F34: 16700 | G34: 카페아란 | H34: 접대비
B35: =B6 -> 신한 #672 | C35: 2022.06.24 14:19:48 | D35: BZ뱅크 | E35: 0 | F35: 5739378 | G35: 06전준영급여 | H35: 급여
B36: =B6 -> 신한 #672 | C36: 2022.06.24 14:37:50 | D36: BZ뱅크 | E36: 0 | F36: 5434828 | G36: 김석준 | H36: 급여
B37: =B6 -> 신한 #672 | C37: 2022.06.24 14:37:50 | D37: BZ뱅크 | E37: 0 | F37: 6061058 | G37: 최고은 | H37: 급여
B38: =B6 -> 신한 #672 | C38: 2022.06.24 14:37:51 | D38: BZ뱅크 | E38: 0 | F38: 5646698 | G38: 강진석 | H38: 급여
B39: =B6 -> 신한 #672 | C39: 2022.06.24 14:37:51 | D39: BZ뱅크 | E39: 0 | F39: 2275450 | G39: 고유빈 | H39: 급여
B40: =B6 -> 신한 #672 | C40: 2022.06.24 14:37:52 | D40: BZ뱅크 | E40: 0 | F40: 4904960 | G40: 이태호 | H40: 급여
B41: =B6 -> 신한 #672 | C41: 2022.06.24 14:37:52 | D41: BZ뱅크 | E41: 0 | F41: 2340480 | G41: 최지현 | H41: 급여
...

Sheet 22.7월
B2: 자 금 일 보
J3: 계정과목 | K3: 설명
B4: ※ 자금현황 | G4: 44804 | J4: 복리후생비 | K4: 회식, 식대
B5: 구 분 | C5: 단위 | D5: 전월잔액 | E5: 수 입 | F5: 지 출 | G5: 기준일 기준 잔액 | J5: 여비교통비 | K5: 출장, 대중교통, 대리운전
B6: 신한 #672 | C6: KRW | D6: 91186014 | E6: =sumif(B20:B154,B6,E20:E154) -> 131027419 | F6: =sumif(B20:B172,B6,F20:F172) -> 92085443 | G6: =D6+E6-F6 -> 130127990 | J6: 비품 | K6: 가구, 가전등 개당 단가 150만원이 넘는 용품
B7: WISE USD | C7: USD | E7: =sumif(B20:B172,B7,E20:E129) -> 0 | F7: =sumif(B20:B172,B7,F20:F172) -> 0 | G7: =D7+E7-F7 -> 0 | J7: 소모품비 | K7: 비품(150만원)으로 잡기에는 금액이 작은 비품
B8: WISE SGD | C8: SGD | E8: =sumif(B20:B129,B8,E20:E172) -> 0 | F8: =sumif(B20:B172,B8,F20:F172) -> 0 | G8: =D8+E8-F8 -> 0 | J8: 사무용품비 | K8: 비품, 소모품비를 제외한 업무용 사무용품 구입
B9: WISE KRW | C9: KRW | E9: =sumif(B20:B129,B9,E20:E129) -> 0 | F9: =sumif(B20:B172,B9,F20:F172) -> 0 | G9: =D9+E9-F9 -> 0 | J9: 통신비 | K9: 등기, 퀵 사용비
J10: 접대비 | K10: 외부 미팅
J11: 세금과공과 | K11: 세금 납부시
J12: 지급수수료 | K12: sms 수수료, 송금 수수료, 일반적으로 발생되는 모든 비용
B13: KRW 합 계 | J13: 미수금 | K13: 돌려 받을 예정인 금액 (ex. 부가세 환급금)
B14: USD 합 계 | J14: 용역비 | K14: 외주용역비
J15: 급여 | K15: 직원 급여
J16: 임차보증금 | K16: 보증금
J17: 서비스용역매출 | K17: 싱가폴 -> 한국 지사 송금
B18: ※ 세부내역
B19: 구 분 | C19: 날 짜 | D19: 은 행 적 요 | E19: 수입 | F19: 지출 | G19: 상세메모 | H19: 계정과목
B20: =B6 -> 신한 #672 | C20: 2022.07.01 00:29:33 | D20: 신한체 | E20: 0 | F20: 100 | G20: 택시_우티택시_ | H20: 여비교통비
B21: =B6 -> 신한 #672 | C21: 2022.07.01 00:29:46 | D21: 신한체 | E21: 100 | F21: 0 | G21: 택시_우티택시_ | H21: 여비교통비
B22: =B6 -> 신한 #672 | C22: 2022.07.01 00:29:49 | D22: 신한체 | E22: 0 | F22: 1000 | G22: 택시_우티택시_ | H22: 여비교통비
B23: =B6 -> 신한 #672 | C23: 2022.07.01 00:36:22 | D23: 신한체 | E23: 1000 | F23: 0 | G23: 택시_우티택시_ | H23: 여비교통비
B24: =B6 -> 신한 #672 | C24: 2022.07.01 00:38:33 | D24: 신한체 | E24: 0 | F24: 19400 | G24: 카카오택시(선 | H24: 여비교통비
B25: =B6 -> 신한 #672 | C25: 2022.07.01 00:38:34 | D25: 신한체 | E25: 19400 | F25: 0 | G25: 카카오택시(선 | H25: 여비교통비
B26: =B6 -> 신한 #672 | C26: 2022.07.01 00:56:14 | D26: 신한체 | E26: 0 | F26: 15400 | G26: 카카오페이(택 | H26: 여비교통비
B27: =B6 -> 신한 #672 | C27: 2022.07.01 00:56:15 | D27: 신한체 | E27: 0 | F27: 3000 | G27: 카카오페이(택 | H27: 여비교통비
B28: =B6 -> 신한 #672 | C28: 2022.07.01 01:24:58 | D28: 신한체 | E28: 0 | F28: 51563 | G28: MPOS*CONCEPT | H28: 여비교통비
B29: =B6 -> 신한 #672 | C29: 2022.07.01 14:19:05 | D29: 신한체 | E29: 0 | F29: 21093 | G29: TASTE OF SAIGO | H29: 여비교통비
B30: =B6 -> 신한 #672 | C30: 2022.07.01 14:24:43 | D30: 신한체 | E30: 0 | F30: 4442 | G30: TCH - 1011815 | H30: 여비교통비
B31: =B6 -> 신한 #672 | C31: 2022.07.01 15:53:27 | D31: 신한체 | E31: 0 | F31: 7416 | G31: ARYA CONSUMER | H31: 여비교통비
B32: =B6 -> 신한 #672 | C32: 2022.07.01 21:52:03 | D32: 신한체 | E32: 0 | F32: 5302 | G32: SASCO-G19D10 | H32: 여비교통비
B33: =B6 -> 신한 #672 | C33: 2022.07.02 08:39:32 | D33: 신한체 | E33: 0 | F33: 45000 | G33: 인천국제공항공 | H33: 여비교통비
B34: =B6 -> 신한 #672 | C34: 2022.07.03 13:13:13 | D34: 신한체 | E34: 0 | F34: 11600 | G34: 카카오택시 선 | H34: 여비교통비
B35: =B6 -> 신한 #672 | C35: 2022.07.03 13:13:14 | D35: 신한체 | E35: 11600 | F35: 0 | G35: 카카오택시 선 | H35: 여비교통비
B36: =B6 -> 신한 #672 | C36: 2022.07.03 13:35:27 | D36: 신한체 | E36: 0 | F36: 10700 | G36: 카카오개인택시 | H36: 여비교통비
B37: =B6 -> 신한 #672 | C37: 2022.07.04 13:50:05 | D37: 신한체 | E37: 0 | F37: 25000 | G37: 소담칼국수 | H37: 접대비
B38: =B6 -> 신한 #672 | C38: 2022.07.04 17:40:02 | D38: BZ공과 | E38: 0 | F38: 2071630 | G38: 국세납부 | H38: 세금과공과
B39: =B6 -> 신한 #672 | C39: 2022.07.04 17:44:54 | D39: BZ공과 | E39: 0 | F39: 207120 | G39: 서울시지방세 | H39: 세금과공과
B40: =B6 -> 신한 #672 | C40: 2022.07.04 18:18:23 | D40: 신한체 | E40: 0 | F40: 6000 | G40: 스마트로(비) | H40: 여비교통비
B41: =B6 -> 신한 #672 | C41: 2022.07.05 12:52:31 | D41: 신한체 | E41: 0 | F41: 10800 | G41: 투썸플레이스( | H41: 접대비
...

Sheet 22.8월
B2: 자 금 일 보
J3: 계정과목 | K3: 설명
B4: ※ 자금현황 | G4: 44804 | J4: 복리후생비 | K4: 회식, 식대
B5: 구 분 | C5: 단위 | D5: 전월잔액 | E5: 수 입 | F5: 지 출 | G5: 기준일 기준 잔액 | J5: 여비교통비 | K5: 출장, 대중교통, 대리운전
B6: 신한 #672 | C6: KRW | D6: 130127990 | E6: =sumif(B20:B129,B6,E20:E129) -> 2611400 | F6: =sumif(B20:B172,B6,F20:F172) -> 74432901 | G6: =D6+E6-F6 -> 58306489 | J6: 비품 | K6: 가구, 가전등 개당 단가 150만원이 넘는 용품
B7: WISE USD | C7: USD | D7: 164894.9 | E7: =sumif(B20:B172,B7,E20:E129) -> 0 | F7: =sumif(B20:B172,B7,F20:F172) -> 2123.31 | G7: =D7+E7-F7 -> 162771.59 | J7: 소모품비 | K7: 비품(150만원)으로 잡기에는 금액이 작은 비품
B8: WISE SGD | C8: SGD | D8: 30914.81 | E8: =sumif(B20:B129,B8,E20:E172) -> 0 | F8: =sumif(B20:B172,B8,F20:F172) -> 9070.92 | G8: =D8+E8-F8 -> 21843.89 | J8: 사무용품비 | K8: 비품, 소모품비를 제외한 업무용 사무용품 구입
B9: WISE KRW | C9: KRW | D9: 393788 | E9: =sumif(B20:B129,B9,E20:E129) -> 0 | F9: =sumif(B20:B172,B9,F20:F172) -> 393788 | G9: =D9+E9-F9 -> 0 | J9: 통신비 | K9: 등기, 퀵 사용비
J10: 접대비 | K10: 외부 미팅
J11: 세금과공과 | K11: 세금 납부시
J12: 지급수수료 | K12: sms 수수료, 송금 수수료, 일반적으로 발생되는 모든 비용
B13: KRW 합 계 | J13: 미수금 | K13: 돌려 받을 예정인 금액 (ex. 부가세 환급금)
B14: USD 합 계 | J14: 용역비 | K14: 외주용역비
J15: 급여 | K15: 직원 급여
B18: ※ 세부내역
B19: 구 분 | C19: 날 짜 | D19: 은 행 적 요 | E19: 수입 | F19: 지출 | G19: 상세메모 | H19: 계정과목
B20: 신한 #672 | C20: 2022.08.01 | D20: 황해도찹쌀순대 | E20: 0 | F20: 84000 | G20: 일반음식점 - 황해도찹쌀순대 | H20: 접대비
B21: 신한 #672 | C21: 2022.08.01 | D21: (주)부자되세요 | E21: 0 | F21: 42000 | G21: 일반음식점 - 창고43 강남점 | H21: 접대비
B22: 신한 #672 | C22: 2022.08.01 | D22: 티머니 개인택 | E22: 0 | F22: 6800 | G22: 택시비 | H22: 여비교통비
B23: 신한 #672 | C23: 2022.08.01 | D23: 카카오택시(선 | E23: 0 | F23: 8700 | G23: 택시비 | H23: 여비교통비
B24: 신한 #672 | C24: 2022.08.01 | D24: 카카오택시(선 | E24: 8700 | F24: 0 | G24: 택시비 | H24: 여비교통비
B25: 신한 #672 | C25: 2022.08.01 | D25: 카카오페이(택 | E25: 0 | F25: 8300 | G25: 택시비 | H25: 여비교통비
B26: 신한 #672 | C26: 2022.08.01 | D26: (주)해담채강남 | E26: 0 | F26: 1109100 | G26: 일반음식점 - 해담채강남점 | H26: 복리후생비
B27: 신한 #672 | C27: 2022.08.01 | D27: (주)해담채강남 | E27: 1109100 | F27: 0 | G27: 일반음식점 - 해담채강남점 (할인위해 취소함) | H27: 복리후생비
B28: 신한 #672 | C28: 2022.08.01 | D28: (주)해담채강남 | E28: 0 | F28: 1019000 | G28: 일반음식점 - 해담채강남점 (할인가로 재결제) | H28: 복리후생비
B29: 신한 #672 | C29: 2022.08.01 | D29: 짬뽕지존 역삼 | E29: 0 | F29: 208000 | G29: 일반음식점 - 짬뽕지존 역삼점 | H29: 복리후생비
B30: 신한 #672 | C30: 2022.08.02 | D30: 신동궁감자탕뼈 | E30: 0 | F30: 108000 | G30: 일반음식점 - 신동궁감자탕 | H30: 복리후생비
B31: 신한 #672 | C31: 2022.08.02 | D31: 카카오택시(선 | E31: 51600 | F31: 0 | G31: 택시비 | H31: 여비교통비
... B48: 신한 #672 | C48: 2022.08.05 | D48: 명함제작비 | E48: 0 | F48: 349800 | G48: 명함통- 명함제작비 | H48: 사무용품비
B49: 신한 #672 | C49: 2022.08.08 | D49: 명함제작비 | E49: 0 | F49: 52800 | G49: 명함통 - 명함제작비 (추가금:별색) | H49: 사무용품비 | I49: =F49*1300 -> 68640000
B50: 신한 #672 | C50: 2022.08.08 | D50: 인천->호치민 | E50: 0 | F50: 1002600 | G50: 비행기표 - 인천->호치민 | H50: 여비교통비
B51: 신한 #672 | C51: 2022.08.08 | D51: 호치민->인천 | E51: 0 | F51: 355600 | G51: 비행기표 - 호치민->인천 | H51: 여비교통비
B52: 신한 #672 | C52: 2022.08.08 | D52: 채선당 사계리 | E52: 0 | F52: 54700 | G52: 일반음식점 - 채선당 사계리점 | H52: 접대비
B53: 신한 #672 | C53: 2022.08.09 | D53: 이슬님컴퓨터 | E53: 0 | F53: 1439420 | G53: 신규입사자 컴퓨터 구매 - 이슬님 | H53: 소모품비
B54: 신한 #672 | C54: 2022.08.09 | D54: 한무쇼핑(주)무 | E54: 0 | F54: 19000 | G54: 현대백화점 무역센터점 - 식품관 | H54: 접대비
B55: 신한 #672 | C55: 2022.08.10 | D55: 2207국민건강 | E55: 0 | F55: 3149360 | G55: 202207국민건강 | H55: 세금과공과
B56: 신한 #672 | C56: 2022.08.10 | D56: 2207국민연금 | E56: 0 | F56: 3202000 | G56: 202207국민연금 | H56: 세금과공과
B57: 신한 #672 | C57: 2022.08.10 | D57: 2207고용보험 | E57: 0 | F57: 746470 | G57: 202207고용보험 | H57: 세금과공과
B58: 신한 #672 | C58: 2022.08.10 | D58: 2207산재보험 | E58: 0 | F58: 278420 | G58: 202207산재보험 | H58: 세금과공과
B59: 신한 #672 | C59: 2022.08.10 | D59: 잔고증명영사 | E59: 0 | F59: 309500 | G59: 잔고증명서 영사인증 진행비 (위드문) | H59: 지급수수료
...

Sheet 22.9월
B2: 자 금 일 보
J3: 계정과목 | K3: 설명
B4: ※ 자금현황 | G4: 기준일: 2022.09.30 | J4: 복리후생비 | K4: 회식, 식대
B5: 구 분 | C5: 단위 | D5: 전월잔액 | E5: 수 입 | F5: 지 출 | G5: 기준일 기준 잔액 | J5: 여비교통비 | K5: 출장, 대중교통, 대리운전
B6: 신한 #672 | C6: KRW | D6: 58306489 | E6: =sumif(B20:B107,B6,E20:E107) -> 21402 | F6: =sumif(B20:B107,B6,F20:F107) -> 33969133 | G6: =D6+E6-F6 -> 24358758 | J6: 비품 | K6: 가구, 가전등 개당 단가 150만원이 넘는 용품
B7: WISE USD | C7: USD | D7: 162771.59 | E7: =sumif(B20:B107,B7,E20:E107) -> 0 | F7: =sumif(B20:B107,B7,F20:F107) -> 105398.73 | G7: =D7+E7-F7 -> 57372.86 | J7: 소모품비 | K7: 비품(150만원)으로 잡기에는 금액이 작은 비품
B8: WISE SGD | C8: SGD | D8: 21843.89 | E8: =sumif(B20:B107,B8,E20:E107) -> 0 | F8: =sumif(B20:B107,B8,F20:F107) -> 7963.21 | G8: =D8+E8-F8 -> 13880.68 | J8: 사무용품비 | K8: 비품, 소모품비를 제외한 업무용 사무용품 구입
B9: WISE KRW | C9: KRW | D9: 0 | E9: =sumif(B20:B107,B9,E20:E107) -> 0 | F9: =sumif(B20:B107,B9,F20:F107) -> 0 | G9: =D9+E9-F9 -> 0 | J9: 통신비 | K9: 등기, 퀵 사용비
B10: 신한 #543 | C10: USD | D10: 0 | E10: =sumif(B20:B107,B10,E20:E107) -> 199975.6 | F10: =sumif(B20:B107,B10,F20:F107) -> 0 | G10: =D10+E10-F10 -> 199975.6 | J10: 접대비 | K10: 외부 미팅
B11: 하나 #304 | C11: KRW | D11: 0 | E11: =sumif(B20:B107,B11,E20:E107) -> 139598000 | F11: =sumif(B20:B107,B11,F20:F107) -> 52356488 | G11: =D11+E11-F11 -> 87241512 | J11: 세금과공과 | K11: 세금 납부시
B12: 하나 #138 | C12: USD | D12: 0 | E12: =sumif(B20:B107,B12,E20:E107) -> 100000 | F12: =sumif(B20:B107,B12,F20:F107) -> 100000 | G12: =D12+E12-F12 -> 0 | J12: 지급수수료 | K12: sms 수수료, 송금 수수료, 일반적으로 발생되는 모든 비용
B13: KRW 합 계 | J13: 미수금 | K13: 돌려 받을 예정인 금액 (ex. 부가세 환급금)
B14: USD 합 계 | J14: 용역비 | K14: 외주용역비
J15: 급여 | K15: 직원 급여
J16: 서비스용역매출 | K16: 싱가폴 -> 한국 지사 송금
J17: 광고매출 | K17: 타법인 매출
B18: ※ 세부내역 | J18: 보통예금 | K18: 예금간 이체
B19: 구 분 | C19: 날 짜 | D19: 은 행 적 요 | E19: 수입 | F19: 지출 | G19: 상세메모 | H19: 계정과목
B20: 신한 #543 | C20: 2022.09.23 | D20: FTX DIGITAL MA | E20: 199975.6 | F20: 0 | G20: 싱가폴 법인 - 마케팅 대행비 입금 | H20: 서비스용역매출
B21: 신한 #672 | C21: 2022.09.02 | D21: 진심 왕돈까스 | E21: 0 | F21: 31500 | G21: 일반음식점 - 진심 왕돈까스 | H21: 접대비
B22: 신한 #672 | C22: 2022.09.02 | D22: 08개인비용Baht | E22: 0 | F22: 146020 | G22: 2022.08월 바트 개인비용정산 | H22: 지급수수료
B23: 신한 #672 | C23: 2022.09.02 | D23: 08개인비용-Gon | E23: 0 | F23: 29200 | G23: 2022.08월 고니 개인비용정산 | H23: 지급수수료
B24: 신한 #672 | C24: 2022.09.02 | D24: 08개인비용-Jin | E24: 0 | F24: 81000 | G24: 2022.08월 진 개인비용정산 | H24: 지급수수료
B25: 신한 #672 | C25: 2022.09.02 | D25: 08월법률자문료 | E25: 0 | F25: 3025000 | G25: 2022.08월 비앤케이 법률자문료 | H25: 지급수수료
B26: =B6 -> 신한 #672 | C26: 2022.09.02 19:01:51 | D26: 두나무주 | E26: 0 | F26: 600000 | G26: UDC2022 티켓 구매 (2장 - 펠릭스,아이작) | H26: 여비교통비
B27: =B6 -> 신한 #672 | C27: 2022.09.05 12:09:07 | D27: 한국철도공사 ( | E27: 0 | F27: 59800 | G27: UDC2022 출장 - 기차표 | H27: 여비교통비
B28: =B6 -> 신한 #672 | C28: 2022.09.05 12:20:03 | D28: SR | E28: 0 | F28: 52000 | G28: UDC2022출장 - 기차표 | H28: 여비교통비
B29: 신한 #672 | C29: 2022.09.02 | D29: 고유빈 | E29: 0 | F29: 32500 | G29: 2022.08월 코빈 개인비용정산 | H29: 지급수수료
B30: 신한 #672 | C30: 2022.09.06 | D30: 법원행정처 | E30: 0 | F30: 1000 | G30: 법원행정처 | H30: 지급수수료
B31: 신한 #672 | C31: 2022.09.06 | D31: 09소득세 | E31: 0 | F31: 2537830 | G31: 2022.09월 소득세 | H31: 세금과공과
B32: 신한 #672 | C32: 2022.09.06 | D32: 09주민세 | E32: 0 | F32: 253720 | G32: 2022.09월 주민세 | H32: 세금과공과
B33: 신한 #672 | C33: 2022.09.07 | D33: 진_축하금 | E33: 0 | F33: 300000 | G33: 진 배우자 출산 축하금 | H33: 지급수수료
B34: 신한 #672 | C34: 2022.09.13 | D34: 2208국민건강 | E34: 0 | F34: 4086460 | G34: 2022.08 국민건강 | H34: 세금과공과
B35: 신한 #672 | C35: 2022.09.13 | D35: 2208국민연금 | E35: 0 | F35: 4182900 | G35: 2022.08 국민연금 | H35: 세금과공과
B36: 신한 #672 | C36: 2022.09.13 | D36: 2208고용보험 | E36: 0 | F36: 941000 | G36: 2022.08 고용보험 | H36: 세금과공과
B37: 신한 #672 | C37: 2022.09.13 | D37: 2208산재보험 | E37: 0 | F37: 348680 | G37: 2022.08 산재보험 | H37: 세금과공과
B38: 신한 #672 | C38: 2022.09.15 | D38: 코스콤 | E38: 0 | F38: 110000 | G38: 법인 범용 공인인증서 발급 | H38: 지급수수료
B39: 신한 #672 | C39: 2022.09.16 | D39: 노무법인청안 | E39: 0 | F39: 110000 | G39: 노무법인 청안 컨설팅료 | H39: 지급수수료
B40: 신한 #672 | C40: 2022.09.17 | D40: 06.18~09.16 | E40: 21396 | F40: 0 | G40: 은행 이자 | H40: 미수금
... B43: 신한 #672 | C43: 2022.09.21 | D43: PAYPAL PTE | E43: 5 | F43: 0 | G43: PAYPAL PTE | H43: 미수금
...

Sheet 22.10월
B2: 자 금 일 보
J3: 계정과목 | K3: 설명
B4: ※ 자금현황 | G4: 기준일: 2022.10.31 | J4: 복리후생비 | K4: 회식, 식대
B5: 구 분 | C5: 단위 | D5: 전월잔액 | E5: 수 입 | F5: 지 출 | G5: 기준일 기준 잔액 | J5: 여비교통비 | K5: 출장, 대중교통, 대리운전
B6: 신한 #672 | C6: KRW | D6: ='22.9월'!G6 -> 24358758 | E6: =sumif(B20:B61,B6,E20:E61) -> 143690000 | F6: =sumif(B20:B61,B6,F20:F61) -> 32442224 | G6: =D6+E6-F6 -> 135606534 | J6: 비품 | K6: 가구, 가전등 개당 단가 150만원이 넘는 용품
B7: WISE USD | C7: USD | D7: ='22.9월'!G7 -> 57372.86 | E7: =sumif(B20:B61,B7,E20:E61) -> 0 | F7: =sumif(B20:B61,B7,F20:F61) -> 10094.39 | G7: =D7+E7-F7 -> 47278.47 | J7: 소모품비 | K7: 비품(150만원)으로 잡기에는 금액이 작은 비품
B8: WISE SGD | C8: SGD | D8: ='22.9월'!G8 -> 13880.68 | E8: =sumif(B20:B61,B8,E20:E61) -> 0 | F8: =sumif(B20:B61,B8,F20:F61) -> 9203.93 | G8: =D8+E8-F8 -> 4676.75 | J8: 사무용품비 | K8: 비품, 소모품비를 제외한 업무용 사무용품 구입
B9: WISE KRW | C9: KRW | D9: ='22.9월'!G9 -> 0 | E9: =sumif(B20:B61,B9,E20:E61) -> 0 | F9: =sumif(B20:B61,B9,F20:F61) -> 0 | G9: =D9+E9-F9 -> 0 | J9: 통신비 | K9: 등기, 퀵 사용비
B10: 신한 #543 | C10: USD | D10: ='22.9월'!G10 -> 199975.6 | E10: =sumif(B20:B61,B10,E20:E61) -> 0 | F10: =sumif(B20:B61,B10,F20:F61) -> 100000 | G10: =D10+E10-F10 -> 99975.6 | J10: 접대비 | K10: 외부 미팅
B11: 하나 #304 | C11: KRW | D11: ='22.9월'!G11 -> 87241512 | E11: =sumif(B20:B61,B11,E20:E61) -> 0 | F11: =sumif(B20:B61,B11,F20:F61) -> 57494593 | G11: =D11+E11-F11 -> 29746919 | J11: 세금과공과 | K11: 세금 납부시
B12: 하나 #138 | C12: USD | D12: ='22.9월'!G12 -> 0 | E12: =sumif(B20:B61,B12,E20:E61) -> 0 | F12: =sumif(B20:B61,B12,F20:F61) -> 0 | G12: =D12+E12-F12 -> 0 | J12: 지급수수료 | K12: sms 수수료, 송금 수수료, 일반적으로 발생되는 모든 비용
B13: KRW 합 계 | D13: =D6+D9+D11 -> 111600270 | E13: =E6+E9+E11 -> 143690000 | F13: =F6+F9+F11 -> 89936817 | G13: =G6+G9+G11 -> 165353453 | J13: 미수금 | K13: 돌려 받을 예정인 금액 (ex. 부가세 환급금)
B14: USD 합 계 | D14: =D7+D10+D12 -> 257348.46 | E14: =E7+E10+E12 -> 0 | F14: =F7+F10+F12 -> 110094.39 | G14: =G7+G10+G12 -> 147254.07 | H14: =rounddown(G14*1420.9,0) -> 209233308 | J14: 용역비 | K14: 외주용역비
B15: SGD 합 계 | D15: =D8 -> 13880.68 | E15: =E8 -> 0 | F15: =F8 -> 9203.93 | G15: =G8 -> 4676.75 | J15: 급여 | K15: 직원 급여
J16: 서비스용역매출 | K16: 싱가폴 -> 한국 지사 송금
J17: 광고매출 | K17: 타법인 매출
B18: ※ 세부내역 | J18: 보통예금 | K18: 예금간 이체
B19: 구 분 | C19: 날 짜 | D19: 은 행 적 요 | E19: 수입 | F19: 지출 | G19: 상세메모 | H19: 계정과목
B20: 신한 #543 | C20: 2022.10.24 | D20: 환전 | E20: 0 | F20: 100000 | G20: 싱가폴 법인 - 운영비 환전 | H20: 보통예금
B21: 신한 #672 | C21: 2022.10.06 | D21: 법률사무소 비앤케이 | E21: 0 | F21: 825000 | G21: 09월법률자문료 | H21: 지급수수료
B22: 신한 #672 | C22: 2022.10.06 | D22: 09근로소득세 | E22: 0 | F22: 3598860 | G22: 09근로소득세 | H22: 세금과공과 | K22: 135606534
B23: 신한 #672 | C23: 2022.10.06 | D23: 09사업소득세 | E23: 0 | F23: 75000 | G23: 09사업소득세 | H23: 세금과공과 | K23: 47278.47
B24: 신한 #672 | C24: 2022.10.06 | D24: 09지방소득세 | E24: 0 | F24: 367320 | G24: 09지방소득세 | H24: 세금과공과 | K24: 4676.75
B25: 신한 #672 | C25: 2022.10.11 | D25: 2022.10.11 07:03:03 | E25: 0 | F25: 4406280 | G25: 2209국민건강 | H25: 세금과공과 | K25: 0
B26: 신한 #672 | C26: 2022.10.11 | D26: 2209국민연금 | E26: 0 | F26: 4511360 | G26: 2209국민연금 | H26: 세금과공과 | K26: 99975.6
B27: 신한 #672 | C27: 2022.10.11 | D27: 2209고용보험 | E27: 0 | F27: 1069990 | G27: 2209고용보험 | H27: 세금과공과 | K27: 29746919
B28: 신한 #672 | C28: 2022.10.11 | D28: 2209산재보험 | E28: 0 | F28: 396500 | G28: 2209산재보험 | H28: 세금과공과 | K28: 0
B29: 신한 #672 | C29: 2022.10.13 | D29: 번역공증수수료 | E29: 0 | F29: 34000 | G29: 번역공증수수료 | H29: 지급수수료
B30: 신한 #672 | C30: 2022.10.20 | D30: 이니시스-정기 | E30: 0 | F30: 440 | G30: 사무실 프린트 비용 | H30: 사무용품비
B31: 신한 #672 | C31: 2022.10.20 | D31: OTP수수료 | E31: 0 | F31: 5000 | G31: OTP 추가발급 수수료 | H31: 지급수수료
B32: 신한 #672 | C32: 2022.10.20 | D32: 이니시스-정기 | E32: 0 | F32: 550 | G32: 사무실 프린트 비용 | H32: 사무용품비
B33: 신한 #672 | C33: 2022.10.24 | D33: 공동인증수수료 | E33: 0 | F33: 4400 | G33: 카드,OTP 인증 은행 수수료 | H33: 지급수수료
B34: 신한 #672 | C34: 2022.10.24 | D34: 코오롱엘에스아 | E34: 0 | F34: 1100500 | G34: 부산 출장 숙소비 | H34: 여비교통비
B35: 신한 #672 | C35: 2022.10.24 | D35: 환전 | E35: 143690000 | F35: 0 | G35: 싱가폴 법인 - 운영비 환전 | H35: 보통예금
B36: 신한 #672 | C36: 2022.10.25 | D36: 노무법인청안 | E36: 0 | F36: 110000 | G36: 노무 컨설팅 비용 | H36: 지급수수료
B37: 신한 #672 | C37: 2022.10.25 | D37: 삼덕회계법인 | E37: 0 | F37: 330000 | G37: 회계 기장 대리 비용 | H37: 지급수수료
B38: 신한 #672 | C38: 2022.10.25 | D38: 현대카드(주) | E38: 0 | F38: 7098922 | G38: 현대카드10월사용분 | H38: 지급수수료
B39: 신한 #672 | C39: 2022.10.27 | D39: 비대면바우처_1 | E39: 0 | F39: 800000 | G39: 케이바우처 - GPRO | H39: 지급수수료
B40: 신한 #672 | C40: 2022.10.28 | D40: Risa-개인비용 | E40: 0 | F40: 369600 | G40: Risa 개인비용 정산 | H40: 여비교통비
... B61: WISE USD | C61: 2022.10.26 | D61: Github | E61: 0 | F61: 148 | G61: 인터넷 호스팅 서비스 및 소프트웨어 개발 | H61: 지급수수료

Sheet 22.11월
B1: 자 금 일 보
K2: 계정과목 | L2: 설명
B3: ※ 자금현황 | G3: 기준일: 2022.11.30 | K3: 복리후생비 | L3: 회식, 식대
B4: 구 분 | C4: 단위 | D4: 전월잔액 | E4: 수 입 | F4: 지 출 | G4: 기준일 기준 잔액 | K4: 여비교통비 | L4: 출장, 대중교통, 대리운전
B5: 신한 #672 | C5: KRW | D5: 135606534 | E5: =sumif(B21:B128,B5,E21:E128) -> 136965758 | F5: =sumif(B21:B171,B5,F21:F171) -> 171929206 | G5: =D5+E5-F5 -> 100643086 | K5: 비품 | L5: 가구, 가전등 개당 단가 150만원이 넘는 용품
B6: 신한 #543 | C6: USD | D6: 99975.6 | E6: =sumif(B21:B130,B6,E21:E130) -> 0 | F6: =sumif(B21:B171,B6,F21:F171) -> 99975.6 | G6: =D6+E6-F6 -> 0 | K6: 소모품비 | L6: 비품(150만원)으로 잡기에는 금액이 작은 비품
B7: 하나 #304 | C7: KRW | D7: 29746919 | E7: =sumif(B21:B130,B7,E21:E130) -> 0 | F7: =sumif(B21:B171,B7,F21:F171) -> 2315185 | G7: =D7+E7-F7 -> 27431734 | K7: 사무용품비 | L7: 비품, 소모품비를 제외한 업무용 사무용품 구입
B8: 하나 #138 | C8: USD | D8: 0 | E8: =sumif(B21:B130,B8,E21:E130) -> 0 | F8: =sumif(B21:B171,B8,F21:F171) -> 0 | G8: =D8+E8-F8 -> 0 | K8: 통신비 | L8: 등기, 퀵 사용비
B9: WISE USD | C9: USD | D9: 47278.47 | E9: =sumif(B21:B171,B9,E21:E128) -> 0 | F9: =sumif(B21:B171,B9,F21:F171) -> 14456.91 | G9: =D9+E9-F9 -> 32821.56 | K9: 접대비 | L9: 외부 미팅
B10: WISE SGD | C10: SGD | D10: 4676.75 | E10: =sumif(B21:B128,B10,E21:E171) -> 0 | F10: =sumif(B21:B171,B10,F21:F171) -> 4676.75 | G10: =D10+E10-F10 -> 0 | K10: 세금과공과 | L10: 세금 납부시
B11: WISE KRW | C11: KRW | D11: 0 | E11: =sumif(B21:B130,B11,E21:E130) -> 0 | F11: =sumif(B21:B171,B11,F21:F171) -> 0 | G11: =D11+E11-F11 -> 0 | K11: 지급수수료 | L11: sms 수수료, 송금 수수료, 일반적으로 발생되는 모든 비용
B12: OCBC USD | C12: USD | D12: 7121.24 | E12: =sumif(B21:B130,B12,E21:E130) -> 0 | F12: =sumif(B21:B170,B12,F21:F170) -> 0 | G12: =D12+E12-F12 -> 7121.24 | K12: 미수금 | L12: 돌려 받을 예정인 금액 (ex. 부가세 환급금)
B13: OCBC SGD | C13: SGD | D13: 930 | E13: =sumif(B21:B130,B13,E21:E130) -> 0 | F13: =sumif(B21:B170,B13,F21:F170) -> 20 | G13: =D13+E13-F13 -> 910 | K13: 용역비 | L13: 외주용역비
B15: KRW 합 계 | D15: =D5+D7+D11 -> 165353453 | E15: =E5+E7+E11 -> 136965758 | F15: =F5+F7+F11 -> 174244391 | G15: =G5+G11+G7 -> 128074820 | H15: =G15 -> 128074820 | K15: 급여 | L15: 직원 급여
B16: USD 합 계 | D16: =D6+D8+D9+D12 -> 154375.31 | E16: =E6+E8+E9+E12 -> 0 | F16: =F6+F8+F9+F12 -> 114432.51 | G16: =G9+G6+G8+G12 -> 39942.8 | H16: =rounddown(G16*1335.9,0) -> 53359586 | K16: 서비스용역매출 | L16: 싱가폴 -> 한국 지사 송금
B17: SGD 합 계 | D17: =D10+D13 -> 5606.75 | E17: =E10+E13 -> 0 | F17: =F10+F13 -> 4696.75 | G17: =G10+G13 -> 910 | H17: =rounddown(G17*970.9,0) -> 883519 | K17: 광고매출 | L17: 타법인 매출
H18: =SUM(H15:H17) -> 182317925 | K18: 보통예금 | L18: 예금간 이체
B19: ※ 세부내역
B20: 구 분 | C20: 날 짜 | D20: 은 행 적 요 | E20: 수입 | F20: 지출 | G20: 상세메모 | H20: 계정과목
B21: 신한 #543 | C21: 2022.11.14 | D21: (주)제로엑스앤드코리아 | E21: 0 | F21: 99975.6 | G21: 환전 | H21: 보통예금
B22: 신한 #672 | C22: 2022.11.01 | D22: 김재욱(법률사 | E22: 0 | F22: 825000 | G22: 비앤케이 10월 법률자문료 | H22: 지급수수료
B23: 신한 #672 | C23: 2022.11.02 | D23: 알마validator | E23: 0 | F23: 1013092 | G23: 알마 경비 정산 | H23: 지급수수료
B24: 신한 #672 | C24: 2022.11.01 | D24: 신한체크카드 | E24: 0 | F24: 110 | G24: 컬러 프린트 비용 | H24: 지급수수료
B25: 신한 #672 | C25: 2022.11.07 | D25: 신한카드10월카 | E25: 0 | F25: 200 | G25: 신한카드 10월카드사용알림서비스 이용료 | H25: 지급수수료
B26: 신한 #672 | C26: 2022.11.08 | D26: 10월소득세 | E26: 0 | F26: 4043620 | G26: 10월 소득세 납부 | H26: 세금과공과
B27: 신한 #672 | C27: 2022.11.08 | D27: 10월주민세 | E27: 0 | F27: 404290 | G27: 10월 주민세 납부 | H27: 세금과공과
B28: 신한 #672 | C28: 2022.11.09 | D28: 국세 | E28: 4163130 | F28: 0 | G28: 환급금 | H28: 미수금
B29: 신한 #672 | C29: 2022.11.10 | D29: 의보 | E29: 0 | F29: 4406280 | G29: 2210국민건강 | H29: 세금과공과
B30: 신한 #672 | C30: 2022.11.10 | D30: 연금 | E30: 0 | F30: 4605900 | G30: 2210국민연금 | H30: 세금과공과
B31: 신한 #672 | C31: 2022.11.10 | D31: 보험료 | E31: 0 | F31: 1157270 | G31: 2210고용보험 | H31: 세금과공과
B32: 신한 #672 | C32: 2022.11.10 | D32: 보험료 | E32: 0 | F32: 428860 | G32: 2210산재보험 | H32: 세금과공과
B33: 신한 #672 | C33: 2022.11.10 | D33: BZ뱅크 | E33: 0 | F33: 10000500 | G33: 사무실계약금 | H33: 지급수수료
B34: 신한 #672 | C34: 2022.11.14 | D34: 환전 | E34: 132637628 | G34: 환전 입금 | H34: 보통예금
B35: 신한 #672 | C35: 2022.11.14 | D35: 공증문서번역비 | E35: 0 | F35: 330500 | G35: 공증문서번역비 | H35: 지급수수료 | K35: =F15-SUM(F33,F35,F43,F46,F63,F64,F65) -> 84736891 | L35: 1회성 제외
B36: 신한 #672 | C36: 2022.11.14 | D36: 신한체크 | E36: 0 | F36: 110 | G36: 프린트비 | H36: 지급수수료 | K36: =K35-SUM(F62,F66) -> 78760310 | L36: 법카 제외 금액
B37: 신한 #672 | C37: 2022.11.14 | D37: 신한체크 | E37: 0 | F37: 110 | G37: 프린트비 | H37: 지급수수료 | K37: =SUM(F69:F82)*1300 -> 24873758 | L37: 인프라 비용, Chris
B38: 신한 #672 | C38: 2022.11.14 | D38: 신한체크 | E38: 0 | F38: 110 | G38: 프린트비 | H38: 지급수수료 | K38: =SUM(K36:K37) -> 103634068
B39: 신한 #672 | C39: 2022.11.14 | D39: 신한체크 | E39: 0 | F39: 550 | G39: 프린트비 | H39: 지급수수료
B40: 신한 #672 | C40: 2022.11.15 | D40: 명함 제작비 | E40: 0 | F40: 17000 | G40: 명함 제작비 - 케빈 | H40: 지급수수료
B41: 신한 #672 | C41: 2022.11.16 | D41: 명함 배송비 | E41: 0 | F41: 9000 | G41: 명함 배송비 | H41: 지급수수료
...

Sheet 22.12월
B1: 자 금 일 보
I2: Currency | J2: KRW | L2: 계정과목 | M2: 설명
B3: ※ 자금현황 | G3: 기준일: 2022.12.31 | I3: USD | J3: 1267.3 | L3: 광고매출 | M3: 타법인 매출
B4: 구 분 | C4: 단위 | D4: 전월잔액 | E4: 수 입 | F4: 지 출 | G4: 기준일 기준 잔액 | I4: SGD | J4: 943.11 | L4: 급여 | M4: 직원 급여
B5: 신한 #672 | C5: KRW | D5: 100640086 | E5: =sumif(B22:B129,B5,E22:E129) -> 12619203 | F5: =sumif(B22:B172,B5,F22:F172) -> 56596015 | G5: =D5+E5-F5 -> 56663274 | L5: 미수금 | M5: 돌려 받을 예정인 금액 (ex. 부가세 환급금)
B6: 신한 #543 | C6: USD | D6: 0 | E6: =sumif(B22:B131,B6,E22:E131) -> 2.31 | F6: =sumif(B22:B172,B6,F22:F172) -> 0 | G6: =D6+E6-F6 -> 2.31 | L6: 보증금 | M6: 보증금 (사무실 임대, 장비 리스 등)
B7: 하나 #304 | C7: KRW | D7: 27431734 | E7: =sumif(B22:B131,B7,E22:E131) -> 130078647 | F7: =sumif(B22:B172,B7,F22:F172) -> 72241082 | G7: =D7+E7-F7 -> 85269299 | L7: 보통예금 | M7: 예금간 이체
B8: 하나 #138 | C8: USD | D8: 0 | E8: =sumif(B22:B131,B8,E22:E131) -> 100000.02 | F8: =sumif(B22:B172,B8,F22:F172) -> 100000 | G8: =D8+E8-F8 -> 0.02 | L8: 복리후생비 | M8: 회식, 식대
B9: WISE USD | C9: USD | D9: 32821.56 | E9: =sumif(B22:B172,B9,E22:E129) -> 115721.12 | F9: =sumif(B22:B172,B9,F22:F172) -> 118357.96 | G9: =D9+E9-F9 -> 30184.72 | L9: 비품 | M9: 가구, 가전등 개당 단가 150만원이 넘는 용품
B10: WISE SGD | C10: SGD | D10: 0 | E10: =sumif(B22:B129,B10,E22:E172) -> 0 | F10: =sumif(B22:B172,B10,F22:F172) -> 0 | G10: =D10+E10-F10 -> 0 | L10: 사무용품비 | M10: 비품, 소모품비를 제외한 업무용 사무용품 구입
B11: WISE KRW | C11: KRW | D11: 0 | E11: =sumif(B22:B131,B11,E22:E131) -> 0 | F11: =sumif(B22:B172,B11,F22:F172) -> 0 | G11: =D11+E11-F11 -> 0 | L11: 서비스용역매출 | M11: 싱가폴 -> 한국 지사 송금
B12: OCBC USD | C12: USD | D12: 7121.24 | E12: =sumif(B22:B131,B12,E22:E131) -> 0 | F12: =sumif(B22:B171,B12,F22:F171) -> 0 | G12: =D12+E12-F12 -> 7121.24 | L12: 세금과공과 | M12: 세금 납부시
B13: OCBC SGD | C13: SGD | D13: 905 | E13: =sumif(B22:B131,B13,E22:E131) -> 0 | F13: =sumif(B22:B171,B13,F22:F171) -> 25 | G13: =D13+E13-F13 -> 880 | L13: 소모품비 | M13: 비품(150만원)으로 잡기에는 금액이 작은 비품
B15: KRW 합 계 | D15: =D5+D7+D11 -> 128071820 | E15: =E5+E7+E11 -> 142697850 | F15: =F5+F7+F11 -> 128837097 | G15: =G5+G11+G7 -> 141932573 | H15: =G15 -> 141932573 | L15: 여비교통비 | M15: 출장, 대중교통, 대리운전
B16: USD 합 계 | D16: =D6+D8+D9+D12 -> 39942.8 | E16: =E6+E8+E9+E12 -> 215723.45 | F16: =F6+F8+F9+F12 -> 218357.96 | G16: =G9+G6+G8+G12 -> 37308.29 | H16: =rounddown(G16*$J$3,0) -> 47280795 | L16: 용역비 | M16: 외주용역비
B17: SGD 합 계 | D17: =D10+D13 -> 905 | E17: =E10+E13 -> 0 | F17: =F10+F13 -> 25 | G17: =G10+G13 -> 880 | H17: =rounddown(G17*$J$4,0) -> 829936 | L17: 접대비 | M17: 외부 미팅
H18: =SUM(H15:H17) -> 190043304 | L18: 지급수수료 | M18: sms 수수료, 송금 수수료, 일반적으로 발생되는 모든 비용
L19: 이자수익 | M19: 은행이자
B20: ※ 세부내역 | L20: 통신비 | M20: 등기, 퀵 사용비
B21: 구 분 | C21: 날 짜 | D21: 은 행 적 요 | E21: 수입 | F21: 지출 | G21: 상세메모 | H21: 계정과목
B22: 신한 #672 | C22: 2022.12.01 | D22: 쇼파 배송비 | E22: 0 | F22: 225500 | G22: 언주 신규 사무실 쇼파 배송료 | H22: 지급수수료
B23: 신한 #672 | C23: 2022.12.05 | D23: Jay 축하금 | E23: 0 | F23: 300500 | G23: 황정원 본인결혼 축하금 | H23: 복리후생비
B24: 신한 #672 | C24: 2022.12.06 | D24: 게임기획외주 | E24: 0 | F24: 2901500 | G24: 게임기획프리랜스비용 (김용애) | H24: 용역비
B25: 신한 #672 | C25: 2022.12.06 | D25: 진 개인비용 | E25: 0 | F25: 23000 | G25: 강진석 11월 개인비용 정산 | H25: 지급수수료
B26: 신한 #672 | C26: 2022.12.06 | D26: 찰스 개인비용 | E26: 0 | F26: 152474 | G26: 권우철 11월 개인비용 정산 | H26: 지급수수료
B27: 신한 #672 | C27: 2022.12.07 | D27: 소득세 | E27: 0 | F27: 4229330 | G27: 11월 소득세 | H27: 세금과공과
B28: 신한 #672 | C28: 2022.12.07 | D28: 사업소득세 | E28: 0 | F28: 90000 | G28: 11월 사업소득세 | H28: 세금과공과
B29: 신한 #672 | C29: 2022.12.07 | D29: 주민세 | E29: 0 | F29: 431860 | G29: 11월주민세 | H29: 세금과공과
B30: 신한 #672 | C30: 2022.12.07 | D30: 11월법률자문료 | E30: 0 | F30: 3025000 | G30: 11월 법률자문료 | H30: 지급수수료
B31: 신한 #672 | C31: 2022.12.07 | D31: 패스트파이브 | E31: 12600000 | F31: 0 | G31: 보증금 환급 | H31: 보증금
B32: 신한 #672 | C32: 2022.12.12 | D32: 의보 | E32: 0 | F32: 5371520 | G32: 건강보험료 | H32: 세금과공과
B33: 신한 #672 | C33: 2022.12.12 | D33: 보험료 | E33: 0 | F33: 1298340 | G33: 고용보험료 | H33: 세금과공과
B34: 신한 #672 | C34: 2022.12.12 | D34: 연금 | E34: 0 | F34: 5544600 | G34: 국민연금 | H34: 세금과공과 | J34: 56663274
B35: 신한 #672 | C35: 2022.12.12 | D35: 보험료 | E35: 0 | F35: 481160 | G35: 산재보험료 | H35: 세금과공과 | J35: 0
B36: 신한 #672 | C36: 2022.12.12 | D36: 서비스 | E36: 0 | F36: 440000 | G36: 세콤 이용료 | H36: 지급수수료 | J36: 85269299
B37: OCBC SGD | C37: 2022.12.05 | D37: Bank monthly fee | E37: 0 | F37: 10 | G37: Bank monthly fee | H37: 지급수수료 | J37: 100000
B38: WISE USD | C38: 2022.12.01 | D38: Milestone Business Group | E38: 0 | F38: 9936.39 | G38: Chris 12월급여 | H38: 급여 | J38: 30184.72
B39: WISE USD | C39: 2022.12.02 | D39: Google Cloud 84l94z | E39: 0 | F39: 492.46 | G39: Google Cloud 사용료 | H39: 지급수수료 | J39: 0
B40: WISE USD | C40: 2022.12.04 | D40: Name-Cheap.com* F7m0xg | E40: 0 | F40: 64.98 | G40: 도메인 사용료 | H40: 지급수수료 | J40: 0
B41: WISE USD | C41: 2022.12.05 | D41: Google Cloud Wczw3l | E41: 0 | F41: 744.71 | G41: Google Cloud 사용료 | H41: 지급수수료 | J41: 7121.24
...

Sheet 23.01월
B1: 자 금 일 보
I2: Currency | J2: KRW | L2: 계정과목 | M2: 설명
B3: ※ 자금현황 | G3: 기준일: 2023.01.31 | I3: USD | J3: 1228.7 | L3: 광고매출 | M3: 타법인 매출
B4: 구 분 | C4: 단위 | D4: 전월잔액 | E4: 수 입 | F4: 지 출 | G4: 기준일 기준 잔액 | I4: SGD | J4: 934.76 | L4: 급여 | M4: 직원 급여
B5: 신한 #672 | C5: KRW | D5: 56663274 | E5: =sumif(B22:B129,B5,E22:E129) -> 80000000 | F5: =sumif(B22:B172,B5,F22:F172) -> 107409230 | G5: =D5+E5-F5 -> 29254044 | L5: 미수금 | M5: 돌려 받을 예정인 금액 (ex. 부가세 환급금)
B6: 신한 #543 | C6: USD | D6: 2.31 | E6: =sumif(B22:B131,B6,E22:E131) -> 0 | F6: =sumif(B22:B172,B6,F22:F172) -> 0 | G6: =D6+E6-F6 -> 2.31 | L6: 보증금 | M6: 보증금 (사무실 임대, 장비 리스 등)
B7: 하나 #304 | C7: KRW | D7: 85269299 | E7: =sumif(B22:B131,B7,E22:E131) -> 0 | F7: =sumif(B22:B172,B7,F22:F172) -> 82987474 | G7: =D7+E7-F7 -> 2281825 | L7: 보통예금 | M7: 예금간 이체
B8: 하나 #138 | C8: USD | D8: 0.02 | E8: =sumif(B22:B131,B8,E22:E131) -> 0 | F8: =sumif(B22:B172,B8,F22:F172) -> 0 | G8: =D8+E8-F8 -> 0.02 | L8: 복리후생비 | M8: 회식, 식대
B9: WISE USD | C9: USD | D9: 30184.72 | E9: =sumif(B22:B172,B9,E22:E129) -> 134788.82 | F9: =sumif(B22:B172,B9,F22:F172) -> 17800.51 | G9: =D9+E9-F9 -> 147173.03 | L9: 비품 | M9: 가구, 가전등 개당 단가 150만원이 넘는 용품
B10: WISE SGD | C10: SGD | D10: 0 | E10: =sumif(B22:B129,B10,E22:E172) -> 0 | F10: =sumif(B22:B172,B10,F22:F172) -> 0 | G10: =sumif(C22:C172,C10,G22:G172) -> 0 | L10: 사무용품비 | M10: 비품, 소모품비를 제외한 업무용 사무용품 구입
B11: WISE KRW | C11: KRW | D11: 0 | E11: =sumif(B22:B131,B11,E22:E131) -> 0 | F11: =sumif(B22:B172,B11,F22:F172) -> 0 | G11: =D11+E11-F11 -> 0 | L11: 서비스용역매출 | M11: 싱가폴 -> 한국 지사 송금
B12: OCBC USD | C12: USD | D12: 7121.24 | E12: =sumif(B22:B131,B12,E22:E131) -> 0 | F12: =sumif(B22:B171,B12,F22:F171) -> 0 | G12: =D12+E12-F12 -> 7121.24 | L12: 세금과공과 | M12: 세금 납부시
B13: OCBC SGD | C13: SGD | D13: 880 | E13: =sumif(B22:B131,B13,E22:E131) -> 0 | F13: =sumif(B22:B171,B13,F22:F171) -> 0 | G13: =D13+E13-F13 -> 880 | L13: 소모품비 | M13: 비품(150만원)으로 잡기에는 금액이 작은 비품
B15: KRW 합 계 | D15: =D5+D7+D11 -> 141932573 | E15: =E5+E7+E11 -> 80000000 | F15: =F5+F7+F11 -> 190396704 | G15: =G5+G11+G7 -> 31535869 | H15: =G15 -> 31535869 | L15: 여비교통비 | M15: 출장, 대중교통, 대리운전
B16: USD 합 계 | D16: =D6+D8+D9+D12 -> 37308.29 | E16: =E6+E8+E9+E12 -> 134788.82 | F16: =F6+F8+F9+F12 -> 17800.51 | G16: =G9+G6+G8+G12 -> 154296.6 | H16: =rounddown(G16*$J$3,0) -> 189584232 | L16: 용역비 | M16: 외주용역비
B17: SGD 합 계 | D17: =D10+D13 -> 880 | E17: =E10+E13 -> 0 | F17: =F10+F13 -> 0 | G17: =G10+G13 -> 880 | H17: =rounddown(G17*$J$4,0) -> 822588 | L17: 접대비 | M17: 외부 미팅
H18: =SUM(H15:H17) -> 221942689 | I18: =SUM(I15:I17) -> 0 | L18: 지급수수료 | M18: sms 수수료, 송금 수수료, 일반적으로 발생되는 모든 비용
L19: 이자수익 | M19: 은행이자
B20: ※ 세부내역 | L20: 통신비 | M20: 등기, 퀵 사용비
B21: 구 분 | C21: 날 짜 | D21: 은 행 적 요 | E21: 수입 | F21: 지출 | G21: 상세메모 | H21: 계정과목 | L21: 마케팅비 | M21: PR 기사등 마케팅 비용
B22: =B5 -> 신한 #672 | C22: 2023.01.02 | D22: 신규입사장비 | E22: 0 | F22: 5489500 | G22: 맥플러스 신규입사자 장비 구매 | H22: 비품
B23: =B9 -> WISE USD | C23: 2023.01.02 | D23: Google Cloud Bsrtnl | E23: 0 | F23: 14.17 | G23: Google Cloud 사용료 | H23: 지급수수료
B24: =B9 -> WISE USD | C24: 2023.01.02 | D24: Milestone Business Group, LLC. | E24: 0 | F24: 10423.07 | G24: Christ 급여 | H24: 급여
B25: =B5 -> 신한 #672 | C25: 2023.01.04 | D25: 12월 주민세 | E25: 0 | F25: 422860 | G25: 12월 주민세 납부 | H25: 세금과공과
B26: =B5 -> 신한 #672 | C26: 2023.01.04 | D26: 12월 소득세 | E26: 0 | F26: 4229330 | G26: 12월 소득세 납부 | H26: 세금과공과
B27: =B5 -> 신한 #672 | C27: 2023.01.04 | D27: 12월법률자문료 | E27: 0 | F27: 825000 | G27: 비앤케이 12월 법률자문료 | H27: 지급수수료 | L27: 대여금 | M27: 싱가폴 -> 한국 지사 송금
B28: =B5 -> 신한 #672 | C28: 2023.01.04 | D28: 12월언주사무실 | E28: 0 | F28: 5913330 | G28: 12월 그림바우빌딩 임대료,관리비,전기료 | H28: 지급수수료
B29: =B5 -> 신한 #672 | C29: 2023.01.07 | D29: 2212국민건강 | E29: 0 | F29: 5371520 | G29: 12월 국민건강료 | H29: 세금과공과
B30: =B5 -> 신한 #672 | C30: 2023.01.07 | D30: 2212국민연금 | E30: 0 | F30: 5544600 | G30: 12월 국민연금료 | H30: 세금과공과
B31: =B5 -> 신한 #672 | C31: 2023.01.07 | D31: 2212고용보험 | E31: 0 | F31: 1272420 | G31: 12월 고용보험료 | H31: 세금과공과
B32: =B5 -> 신한 #672 | C32: 2023.01.07 | D32: 2212산재보험 | E32: 0 | F32: 471550 | G32: 12월 산재보험료 | H32: 세금과공과
B33: =B5 -> 신한 #672 | C33: 2023.01.10 | D33: Gon-개인비용 | E33: 0 | F33: 4500 | G33: 12월 고니 개인비용 정산 | H33: 지급수수료
B34: =B9 -> WISE USD | C34: 2023.01.11 | D34: Milestone Business Group, LLC. | E34: 0 | F34: 660.39 | G34: 12월 Chris 개인비용 정산 | H34: 지급수수료
B35: =B5 -> 신한 #672 | C35: 2023.01.11 | D35: 서울시세입금 | E35: 0 | F35: 64370 | G35: 미납부 세금 | H35: 세금과공과
B36: =B5 -> 신한 #672 | C36: 2023.01.11 | D36: 메가존소프트 | E36: 0 | F36: 5289865 | G36: 메가존 구글 사용료 | H36: 지급수수료
B37: =B9 -> WISE USD | C37: 2023.01.14 | D37: Postmarkapp.com | E37: 0 | F37: 10 | G37: 개발용 서비스 이용료 | H37: 지급수수료
B38: =B5 -> 신한 #672 | C38: 2023.01.18 | D38: 웰리더PR비용 | E38: 0 | F38: 1208300 | G38: 웰리더 하바 파트너쉽 배포 (PR수수료) | H38: 마케팅비
B39: =B9 -> WISE USD | C39: 2023.01.18 | D39: JUHONG LEE | E39: 0 | F39: 4303.29 | G39: 베트남 법인 청산 비용 | H39: 지급수수료
B40: =B9 -> WISE USD | C40: 2023.01.18 | D40: PRESTO INVESTMENT (BVI) LTD. | E40: 134788.82 | F40: 0 | G40: LN 매도 | H40: 보통예금
B41: =B9 -> WISE USD | C41: 2023.01.19 | D41: Name-Cheap.com * Xfjuxi | E41: 0 | F41: 38.4 | G41: 개발용 서비스 사용료 | H41: 지급수수료
...

Sheet 23.02월
B1: 자 금 일 보
I2: Currency | J2: KRW | L2: 계정과목 | M2: 설명
B3: ※ 자금현황 | G3: 기준일: 2023.02.28 | I3: USD | J3: =IFERROR(__xludf.DUMMYFUNCTION("GOOGLEFINANCE(""USDKRW"")"),1472.7250000000001) -> 1472.725 | L3: 광고매출 | M3: 타법인 매출
B4: 구 분 | C4: 단위 | D4: 전월잔액 | E4: 수 입 | F4: 지 출 | G4: 기준일 기준 잔액 | I4: SGD | J4: =IFERROR(__xludf.DUMMYFUNCTION("GOOGLEFINANCE(""SGDKRW"")"),1143.885) -> 1143.885 | L4: 급여 | M4: 직원 급여
B5: 신한 #672 | C5: KRW | D5: ='23.01월'!G5 -> 29254044 | E5: =sumif(B22:B142,B5,E22:E142) -> 27511820 | F5: =sumif(B22:B185,B5,F22:F185) -> 51478971 | G5: =D5+E5-F5 -> 5286893 | L5: 미수금 | M5: 돌려 받을 예정인 금액 (ex. 부가세 환급금)
B6: 신한 #543 | C6: USD | D6: ='23.01월'!G6 -> 2.31 | E6: =sumif(B22:B144,B6,E22:E144) -> 0 | F6: =sumif(B22:B185,B6,F22:F185) -> 0 | G6: =D6+E6-F6 -> 2.31 | L6: 보증금 | M6: 보증금 (사무실 임대, 장비 리스 등)
B7: 하나 #304 | C7: KRW | D7: ='23.01월'!G7 -> 2281825 | E7: =sumif(B22:B144,B7,E22:E144) -> 148271622 | F7: =sumif(B22:B185,B7,F22:F185) -> 86435272 | G7: =D7+E7-F7 -> 64118175 | L7: 보통예금 | M7: 예금간 이체
B8: 하나 #138 | C8: USD | D8: ='23.01월'!G8 -> 0.02 | E8: =sumif(B22:B144,B8,E22:E144) -> 115426.76 | F8: =sumif(B22:B185,B8,F22:F185) -> 115426 | G8: =D8+E8-F8 -> 0.78 | L8: 복리후생비 | M8: 회식, 식대
B9: WISE USD | C9: USD | D9: ='23.01월'!G9 -> 147173.03 | E9: =sumif(B22:B185,B9,E22:E142) -> 0 | F9: =sumif(B22:B185,B9,F22:F185) -> 138527.06 | G9: =D9+E9-F9 -> 8645.97 | L9: 비품 | M9: 가구, 가전등 개당 단가 150만원이 넘는 용품
B10: WISE SGD | C10: SGD | D10: ='23.01월'!G10 -> 0 | E10: =sumif(B22:B142,B10,E22:E185) -> 0 | F10: =sumif(B22:B185,B10,F22:F185) -> 0 | G10: =D10+E10-F10 -> 0 | L10: 사무용품비 | M10: 비품, 소모품비를 제외한 업무용 사무용품 구입
B11: WISE KRW | C11: KRW | D11: ='23.01월'!G11 -> 0 | E11: =sumif(B22:B144,B11,E22:E144) -> 0 | F11: =sumif(B22:B185,B11,F22:F185) -> 0 | G11: =D11+E11-F11 -> 0 | L11: 서비스용역매출 | M11: 싱가폴 -> 한국 지사 송금
B12: OCBC USD | C12: USD | D12: ='23.01월'!G12 -> 7121.24 | E12: =sumif(B22:B144,B12,E22:E144) -> 0 | F12: =sumif(B22:B184,B12,F22:F184) -> 0 | G12: =D12+E12-F12 -> 7121.24 | L12: 세금과공과 | M12: 세금 납부시
B13: OCBC SGD | C13: SGD | D13: ='23.01월'!G13 -> 880 | E13: =sumif(B22:B144,B13,E22:E144) -> 0 | F13: =sumif(B22:B184,B13,F22:F184) -> 50 | G13: =D13+E13-F13 -> 830 | L13: 소모품비 | M13: 비품(150만원)으로 잡기에는 금액이 작은 비품
L14: 여비교통비 | M14: 출장, 대중교통, 대리운전
B15: KRW 합 계 | D15: =D5+D7+D11 -> 31535869 | E15: =E5+E7+E11 -> 175783442 | F15: =F5+F7+F11 -> 137914243 | G15: =G5+G11+G7 -> 69405068 | H15: =G15 -> 69405068 | L15: 용역비 | M15: 외주용역비
B16: USD 합 계 | D16: =D6+D8+D9+D12 -> 154296.6 | E16: =E6+E8+E9+E12 -> 115426.76 | F16: =F6+F8+F9+F12 -> 253953.06 | G16: =G9+G6+G8+G12 -> 15770.3 | H16: =rounddown(G16*$J$3,0) -> 23225315 | L16: 접대비 | M16: 외부 미팅
B17: SGD 합 계 | D17: =D10+D13 -> 880 | E17: =E10+E13 -> 0 | F17: =F10+F13 -> 50 | G17: =G10+G13 -> 830 | H17: =rounddown(G17*$J$4,0) -> 949424 | L17: 지급수수료 | M17: sms 수수료, 송금 수수료, 일반적으로 발생되는 모든 비용
H18: =SUM(H15:H17) -> 93579807 | I18: =SUM(I15:I17) -> 0 | L18: 이자수익 | M18: 은행이자
L19: 통신비 | M19: 등기, 퀵 사용비
B20: ※ 세부내역
B21: 구 분 | C21: 날 짜 | D21: 은 행 적 요 | E21: 수입 | F21: 지출 | G21: 상세메모 | H21: 계정과목
B22: =B5 -> 신한 #672 | C22: 2023.02.01 | D22: 안양신도판매 | F22: 77000 | G22: 복합기 사용료 지급 | H22: 지급수수료
B23: =B5 -> 신한 #672 | C23: 2023.02.03 | D23: 강남세무서 | E23: 7511820 | G23: 22년 4분기 부가세 환급 | H23: 미수금
B24: =B5 -> 신한 #672 | C24: 2023.02.03 | D24: 법률자문1월 | F24: 825000 | G24: 비앤케이 1월 법률자문료 | H24: 지급수수료
B25: =B5 -> 신한 #672 | C25: 2023.02.03 | D25: 1월임대료 | F25: 6333530 | G25: 1월 그림바우빌딩 임대료,관리비,전기료 | H25: 지급수수료
B26: =B5 -> 신한 #672 | C26: 2023.02.08 | D26: 국세_주식회사 | F26: 4856960 | G26: 근로소득 원천세 지급 | H26: 세금과공과
B27: =B5 -> 신한 #672 | C27: 2023.02.08 | D27: 서울지방제로엑 | F27: 485630 | G27: 근로소득 지방소득세 지급 | H27: 세금과공과
B28: =B5 -> 신한 #672 | C28: 2023.02.10 | D28: 2301국민건강 | F28: 5474480 | G28: 1월 건강보험료 지급 | H28: 세금과공과
B29: =B5 -> 신한 #672 | C29: 2023.02.10 | D29: 2301국민연금 | F29: 6042300 | G29: 1월 연금보험료 지급 | H29: 세금과공과
B30: =B5 -> 신한 #672 | C30: 2023.02.10 | D30: 2301고용보험 | F30: 1272420 | G30: 1월 고용보험료 지급 | H30: 세금과공과
B31: =B5 -> 신한 #672 | C31: 2023.02.10 | D31: 2301산재보험 | F31: 471550 | G31: 1월 산재보험료 지급 | H31: 세금과공과
B32: =B5 -> 신한 #672 | C32: 2023.02.10 | D32: 메가존소프트( | F32: 5541944 | G32: google suite 1월 비용 지급 | H32: 지급수수료
B33: =B5 -> 신한 #672 | C33: 2023.02.10 | D33: 박성준 | F33: 200500 | G33: 넵튠 박성준 본부장 결혼 축의금 지급 | H33: 접대비
B34: =B5 -> 신한 #672 | C34: 2023.02.21 | D34: 세콤 | F34: 110000 | G34: 세콤 비용 지급 | H34: 지급수수료
B35: =B5 -> 신한 #672 | C35: 2023.02.24 | D35: 주식회사 제로엑스앤드코리아 | E35: 20000000 | G35: 계좌간 자금 이체 | H35: 보통예금
B36: =B5 -> 신한 #672 | C36: 2023.02.27 | D36: 코웨이렌탈02 | F36: 37430 | G36: 공청기 | H36: 복리후생비
B37: =B5 -> 신한 #672 | C37: 2023.02.27 | D37: 코웨이렌탈02 | F37: 37430 | G37: 공청기 | H37: 복리후생비
B38: =B5 -> 신한 #672 | C38: 2023.02.27 | D38: 코웨이렌탈02 | F38: 20660 | G38: 비데 | H38: 복리후생비
B39: =B5 -> 신한 #672 | C39: 2023.02.27 | D39: 코웨이렌탈02 | F39: 20660 | G39: 비데 | H39: 복리후생비
B40: =B5 -> 신한 #672 | C40: 2023.02.27 | D40: 코웨이렌탈02 | F40: 50250 | G40: 정수기 | H40: 복리후생비
...

Sheet 23.03월
B1: 자 금 일 보
I2: Currency | J2: KRW | L2: 계정과목 | M2: 설명
B3: ※ 자금현황 | G3: 기준일: 2023.03.31 | I3: USD | J3: =IFERROR(__xludf.DUMMYFUNCTION("GOOGLEFINANCE(""USDKRW"")"),1472.7250000000001) -> 1472.725 | L3: 광고매출 | M3: 타법인 매출
B4: 구 분 | C4: 단위 | D4: 전월잔액 | E4: 수 입 | F4: 지 출 | G4: 기준일 기준 잔액 | I4: SGD | J4: =IFERROR(__xludf.DUMMYFUNCTION("GOOGLEFINANCE(""SGDKRW"")"),1143.885) -> 1143.885 | L4: 급여 | M4: 직원 급여
B5: 신한 #672 | C5: KRW | D5: ='23.02월'!G5 -> 5286893 | E5: =sumif(B22:B142,B5,E22:E142) -> 46006686 | F5: =sumif(B22:B185,B5,F22:F185) -> 21719091 | G5: =D5+E5-F5 -> 29574488 | L5: 미수금 | M5: 돌려 받을 예정인 금액 (ex. 부가세 환급금)
B6: 신한 #543 | C6: USD | D6: ='23.02월'!G6 -> 2.31 | E6: =sumif(B22:B144,B6,E22:E144) -> 0 | F6: =sumif(B22:B185,B6,F22:F185) -> 0 | G6: =D6+E6-F6 -> 2.31 | L6: 보증금 | M6: 보증금 (사무실 임대, 장비 리스 등)
B7: 하나 #304 | C7: KRW | D7: ='23.02월'!G7 -> 64118175 | E7: =sumif(B22:B144,B7,E22:E144) -> 115956794 | F7: =sumif(B22:B185,B7,F22:F185) -> 141909628 | G7: =D7+E7-F7 -> 38165341 | L7: 보통예금 | M7: 예금간 이체
B8: 하나 #138 | C8: USD | D8: ='23.02월'!G8 -> 0.78 | E8: =sumif(B22:B144,B8,E22:E144) -> 91350.11 | F8: =sumif(B22:B185,B8,F22:F185) -> 91350 | G8: =D8+E8-F8 -> 0.89 | L8: 복리후생비 | M8: 회식, 식대
B9: WISE USD | C9: USD | D9: ='23.02월'!G9 -> 8645.97 | E9: =sumif(B22:B185,B9,E22:E142) -> 395592.5 | F9: =sumif(B22:B185,B9,F22:F185) -> 102168.77 | G9: =D9+E9-F9 -> 302069.7 | L9: 비품 | M9: 가구, 가전등 개당 단가 150만원이 넘는 용품
B10: WISE SGD | C10: SGD | D10: ='23.02월'!G10 -> 0 | E10: =sumif(B22:B142,B10,E22:E185) -> 500 | F10: =sumif(B22:B185,B10,F22:F185) -> 300 | G10: =D10+E10-F10 -> 200 | L10: 사무용품비 | M10: 비품, 소모품비를 제외한 업무용 사무용품 구입
B11: WISE KRW | C11: KRW | D11: ='23.02월'!G11 -> 0 | E11: =sumif(B22:B144,B11,E22:E144) -> 0 | F11: =sumif(B22:B185,B11,F22:F185) -> 0 | G11: =D11+E11-F11 -> 0 | L11: 서비스용역매출 | M11: 매출
B12: OCBC USD | C12: USD | D12: ='23.02월'!G12 -> 7121.24 | E12: =sumif(B22:B144,B12,E22:E144) -> 0 | F12: =sumif(B22:B184,B12,F22:F184) -> 0 | G12: =D12+E12-F12 -> 7121.24 | L12: 세금과공과 | M12: 세금 납부시
B13: OCBC SGD | C13: SGD | D13: ='23.02월'!G13 -> 830 | E13: =sumif(B22:B144,B13,E22:E144) -> 0 | F13: =sumif(B22:B184,B13,F22:F184) -> 25 | G13: =D13+E13-F13 -> 805 | L13: 소모품비 | M13: 비품(150만원)으로 잡기에는 금액이 작은 비품
L14: 여비교통비 | M14: 출장, 대중교통, 대리운전
B15: KRW 합 계 | D15: =D5+D7+D11 -> 69405068 | E15: =E5+E7+E11 -> 161963480 | F15: =F5+F7+F11 -> 163628719 | G15: =G5+G11+G7 -> 67739829 | H15: =G15 -> 67739829 | L15: 용역비 | M15: 외주용역비
B16: USD 합 계 | D16: =D6+D8+D9+D12 -> 15770.3 | E16: =E6+E8+E9+E12 -> 486942.61 | F16: =F6+F8+F9+F12 -> 193518.77 | G16: =G9+G6+G8+G12 -> 309194.14 | H16: =rounddown(G16*$J$3,0) -> 455357939 | L16: 접대비 | M16: 외부 미팅
B17: SGD 합 계 | D17: =D10+D13 -> 830 | E17: =E10+E13 -> 500 | F17: =F10+F13 -> 325 | G17: =G10+G13 -> 1005 | H17: =rounddown(G17*$J$4,0) -> 1149604 | L17: 지급수수료 | M17: sms 수수료, 송금 수수료, 일반적으로 발생되는 모든 비용
H18: =SUM(H15:H17) -> 524247372 | I18: =SUM(I15:I17) -> 0 | L18: 이자수익 | M18: 은행이자
L19: 통신비 | M19: 등기, 퀵 사용비
B20: ※ 세부내역 | L20: 마케팅비 | M20: PR 기사등 마케팅 비용
B21: 구 분 | C21: 날 짜 | D21: 은 행 적 요 | E21: 수입 | F21: 지출 | G21: 상세메모 | H21: 계정과목 | L21: 대여금 | M21: 싱가폴 -> 한국 지사 송금
B22: =B5 -> 신한 #672 | C22: 2023.03.02 | D22: 안양신도판매 | F22: 77000 | G22: 복합기 사용료 지급 | H22: 지급수수료
B23: =B5 -> 신한 #672 | C23: 2023.03.03 | D23: 법률자문2월 | F23: 825000 | G23: 비앤케이 2월 법률자문료 | H23: 지급수수료
B24: =B7 -> 하나 #304 | C24: 2023.03.03 | D24: 2월임대료 | F24: =6419820+500 -> 6420320 | G24: 2월 그림바우빌딩 임대료,관리비,전기료 | H24: 지급수수료
B25: =B7 -> 하나 #304 | C25: 2023.03.08 | D25: (주)제로엑스앤드코리아 | F25: 15000500 | G25: 계좌간 자금 이체 | H25: 보통예금
B26: =B7 -> 하나 #304 | C26: 2023.03.08 | D26: 국고_주식회사 제로 | F26: 7975340 | G26: 2월 근로 소득세 | H26: 세금과공과
B27: =B7 -> 하나 #304 | C27: 2023.03.08 | D27: 서울지방제로엑 | F27: 797840 | G27: 2월 근로 지방 소득세 | H27: 세금과공과
B28: =B5 -> 신한 #672 | C28: 2023.03.08 | D28: (주)제로엑스앤드코리아 | E28: 15000000 | G28: 계좌간 자금 이체 | H28: 보통예금
B29: =B7 -> 하나 #304 | C29: 2023.03.08 | D29: 우윤성(디자인멘토) | F29: 330500 | G29: 명함 제작 비용 지급 (3명) | H29: 소모품비
B30: =B7 -> 하나 #304 | C30: 2023.03.08 | D30: 메가존소프트(주) | F30: =4787236+500 -> 4787736 | G30: google suite 2월 비용 지급 | H30: 지급수수료
B31: =B5 -> 신한 #672 | C31: 2023.03.10 | D31: 2302국민건강 | F31: 6058320 | G31: 2월 건강보험료 지급 | H31: 세금과공과
B32: =B5 -> 신한 #672 | C32: 2023.03.10 | D32: 2302국민연금 | F32: 6042300 | G32: 2월 연금보험료 지급 | H32: 세금과공과
B33: =B5 -> 신한 #672 | C33: 2023.03.10 | D33: 2303고용보험 | F33: 1451020 | G33: 2월 고용보험료 지급 | H33: 세금과공과
B34: =B5 -> 신한 #672 | C34: 2023.03.10 | D34: 2302산재보험 | F34: 580720 | G34: 2월 산재보험료 지급 | H34: 세금과공과
B35: =B7 -> 하나 #304 | C35: 2023.03.16 | D35: ㈜ 웰리더 | F35: 1098300 | G35: PR 기사 수수료 | H35: 마케팅비
B36: =B9 -> WISE USD | C36: 2023.03.16 | D36: PRESTO INVESTMENT (BVI) LTD. | E36: 375519.22 | G36: LN 입금 | H36: 광고매출
B37: =B9 -> WISE USD | C37: 2023.03.14 | D37: Postmarkapp.com | F37: 10 | G37: 서비스 이용료 지급 | H37: 지급수수료
B38: =B9 -> WISE USD | C38: 2023.03.16 | D38: ZERO X AND | F38: =371.84 -> 371.84 | G38: 환전 | H38: 보통예금
B39: =B10 -> WISE SGD | C39: 2023.03.16 | D39: ZERO X AND | E39: 500 | G39: 환전 | H39: 보통예금
B40: =B10 -> WISE SGD | C40: 2023.03.16 | D40: EBOS Advisory Pte Ltd | F40: 300 | G40: 정관변경 수수료 | H40: 지급수수료
...

Sheet 23.04월
A1: ㄹ | B1: 자 금 일 보
I2: Currency | J2: KRW | L2: 계정과목 | M2: 설명
B3: ※ 자금현황 | G3: 기준일: 2023.04.28 | I3: USD | J3: =IFERROR(__xludf.DUMMYFUNCTION("GOOGLEFINANCE(""USDKRW"")"),1472.7250000000001) -> 1472.725 | L3: 광고매출 | M3: 타법인 매출
B4: 구 분 | C4: 단위 | D4: 전월잔액 | E4: 수 입 | F4: 지 출 | G4: 기준일 기준 잔액 | I4: SGD | J4: =IFERROR(__xludf.DUMMYFUNCTION("GOOGLEFINANCE(""SGDKRW"")"),1143.885) -> 1143.885 | L4: 급여 | M4: 직원 급여
B5: 신한 #672 | C5: KRW | D5: ='23.03월'!G5 -> 29574488 | E5: =sumif(B22:B123,B5,E22:E123) -> 20000000 | F5: =sumif(B22:B166,B5,F22:F166) -> 32872562 | G5: =D5+E5-F5 -> 16701926 | L5: 미수금 | M5: 돌려 받을 예정인 금액 (ex. 부가세 환급금)
B6: 신한 #543 | C6: USD | D6: ='23.03월'!G6 -> 2.31 | E6: =sumif(B22:B125,B6,E22:E125) -> 0 | F6: =sumif(B22:B166,B6,F22:F166) -> 0 | G6: =D6+E6-F6 -> 2.31 | L6: 보증금 | M6: 보증금 (사무실 임대, 장비 리스 등)
B7: 하나 #304 | C7: KRW | D7: ='23.03월'!G7 -> 38165341 | E7: =sumif(B22:B125,B7,E22:E125) -> 130739000 | F7: =sumif(B22:B166,B7,F22:F166) -> 123293445 | G7: =D7+E7-F7 -> 45610896 | L7: 보통예금 | M7: 예금간 이체
B8: 하나 #138 | C8: USD | D8: ='23.03월'!G8 -> 0.89 | E8: =sumif(B22:B125,B8,E22:E125) -> 100000 | F8: =sumif(B22:B166,B8,F22:F166) -> 100000 | G8: =D8+E8-F8 -> 0.89 | L8: 복리후생비 | M8: 회식, 식대
B9: WISE USD | C9: USD | D9: ='23.03월'!G9 -> 302069.7 | E9: =sumif(B22:B166,B9,E22:E123) -> 0 | F9: =sumif(B22:B166,B9,F22:F166) -> 238296.11 | G9: =D9+E9-F9 -> 63773.59 | L9: 비품 | M9: 가구, 가전등 개당 단가 150만원이 넘는 용품
B10: WISE SGD | C10: SGD | D10: ='23.03월'!G10 -> 200 | E10: =sumif(B22:B123,B10,E22:E166) -> 0 | F10: =sumif(B22:B166,B10,F22:F166) -> 0 | G10: =D10+E10-F10 -> 200 | L10: 사무용품비 | M10: 비품, 소모품비를 제외한 업무용 사무용품 구입
B11: WISE KRW | C11: KRW | D11: ='23.03월'!G11 -> 0 | E11: =sumif(B22:B125,B11,E22:E125) -> 0 | F11: =sumif(B22:B166,B11,F22:F166) -> 0 | G11: =D11+E11-F11 -> 0 | L11: 서비스용역매출 | M11: 매출
B12: OCBC USD | C12: USD | D12: ='23.03월'!G12 -> 7121.24 | E12: =sumif(B25:B117,B12,E25:E99) -> 949990.42 | F12: =sumif(B22:B165,B12,F22:F165) -> 22.39 | G12: =D12+E12-F12 -> 957089.27 | L12: 세금과공과 | M12: 세금 납부시
B13: OCBC SGD | C13: SGD | D13: ='23.03월'!G13 -> 805 | E13: =sumif(B22:B125,B13,E22:E125) -> 0 | F13: =sumif(B22:B165,B13,F22:F165) -> 25 | G13: =D13+E13-F13 -> 780 | L13: 소모품비 | M13: 비품(150만원)으로 잡기에는 금액이 작은 비품
L14: 여비교통비 | M14: 출장, 대중교통, 대리운전
B15: KRW 합 계 | D15: =D5+D7+D11 -> 67739829 | E15: =E5+E7+E11 -> 150739000 | F15: =F5+F7+F11 -> 156166007 | G15: =G5+G11+G7 -> 62312822 | H15: =G15 -> 62312822 | L15: 용역비 | M15: 외주용역비
B16: USD 합 계 | D16: =D6+D8+D9+D12 -> 309194.14 | E16: =E6+E8+E9+E12 -> 1049990.4 | F16: =F6+F8+F9+F12 -> 338318.5 | G16: =G9+G6+G8+G12 -> 1020866.1 | H16: =rounddown(G16*$J$3,0) -> 1503454968 | L16: 접대비 | M16: 외부 미팅
B17: SGD 합 계 | D17: =D10+D13 -> 1005 | E17: =E10+E13 -> 0 | F17: =F10+F13 -> 25 | G17: =G10+G13 -> 980 | H17: =rounddown(G17*$J$4,0) -> 1121007 | L17: 지급수수료 | M17: sms 수수료, 송금 수수료, 일반적으로 발생되는 모든 비용
H18: =SUM(H15:H17) -> 1566888797 | I18: =SUM(I15:I17) -> 0 | L18: 이자수익 | M18: 은행이자
L19: 통신비 | M19: 등기, 퀵 사용비
B20: ※ 세부내역 | L20: 마케팅비 | M20: PR 기사등 마케팅 비용
B21: 구 분 | C21: 날 짜 | D21: 은 행 적 요 | E21: 수입 | F21: 지출 | G21: 상세메모 | H21: 계정과목 | L21: 대여금 | M21: 싱가폴 -> 한국 지사 송금
B22: =B5 -> 신한 #672 | C22: 2023.04.04 | D22: 법률자문3월 | F22: 825000 | G22: 비앤케이 2월 법률자문료 | H22: 지급수수료
B23: =B7 -> 하나 #304 | C23: 2023.04.03 | D23: 3월임대료 | F23: =6198060+500 -> 6198560 | G23: 2월 그림바우빌딩 임대료,관리비,전기료 | H23: 지급수수료
B24: =B9 -> WISE USD | C24: 2023.04.01 | D24: zoom | F24: 161.89 | G24: zoom 비용 지급 | H24: 지급수수료
B25: =B9 -> WISE USD | C25: 2023.04.03 | D25: Milestone Business Group | F25: 11657.73 | G25: Chris 4월 급여 | H25: 급여
B26: =B9 -> WISE USD | C26: 2023.04.03 | D26: wise | F26: 0.39 | G26: Chris 4월 급여 송금 수수료 | H26: 지급수수료 | L26: 1020866.1
B27: =B9 -> WISE USD | C27: 2023.04.05 | D27: Sevio FZC | F27: 36720.98 | G27: 게임 도시 마케팅 비용 지급_PlaytoEarn | H27: 마케팅비
B28: =B9 -> WISE USD | C28: 2023.04.05 | D28: Nguyen Duc Hieu Thao | F28: 10014.39 | G28: 게임 도시 마케팅 비용 지급_Hatten Guild | H28: 마케팅비
B29: =B9 -> WISE USD | C29: 2023.04.05 | D29: Momo Tech Company Limited | F29: 10294.39 | G29: 게임 도시 마케팅 비용 지급_ChainPlay | H29: 마케팅비
B30: =B9 -> WISE USD | C30: 2023.04.05 | D30: SecuChart Global | F30: 18014.39 | G30: 게임 도시 마케팅 비용 지급_P2eAll | H30: 마케팅비
B31: =B9 -> WISE USD | C31: 2023.04.05 | D31: Coin68 Limited | F31: 5014.39 | G31: 게임 도시 마케팅 비용 지급_Acient8 | H31: 마케팅비
B32: =B9 -> WISE USD | C32: 2023.04.05 | D32: UAB DappRadar | F32: 36014.39 | G32: 게임 도시 마케팅 비용 지급_DappRader | H32: 마케팅비
B33: =B9 -> WISE USD | C33: 2023.04.05 | D33: Siam commercial bank | F33: 5364.39 | G33: 게임 도시 마케팅 비용 지급_Guildfi | H33: 마케팅비
B34: =B9 -> WISE USD | C34: 2023.04.06 | D34: Telos Labs Pte. Ltd | F34: 5014.39 | G34: 게임 도시 마케팅 비용 지급_Avocado | H34: 마케팅비
B35: =B5 -> 신한 #672 | C35: 2023.04.10 | D35: 2303국민건강 | F35: 5316960 | G35: 2303국민건강 | H35: 세금과공과
B36: =B5 -> 신한 #672 | C36: 2023.04.10 | D36: 2303국민연금 | F36: 5283520 | G36: 2303국민연금 | H36: 세금과공과
B37: =B5 -> 신한 #672 | C37: 2023.04.10 | D37: 2303고용보험 | F37: 1249620 | G37: 2303고용보험 | H37: 세금과공과
B38: =B5 -> 신한 #672 | C38: 2023.04.10 | D38: 2303산재보험 | F38: 463030 | G38: 2303산재보험 | H38: 세금과공과
B39: =B5 -> 신한 #672 | C39: 2023.04.10 | D39: 삼덕회계법인 | F39: 1650000 | G39: 2022년 결산 세무 조정 | H39: 지급수수료
B40: =B7 -> 하나 #304 | C40: 2023.04.10 | D40: 국고_주식회사제로엑스 | F40: 7138660 | G40: 3월 근로 소득세 | H40: 세금과공과
...

Sheet 23.05월
B1: 자 금 일 보
I2: Currency | J2: KRW | L2: 계정과목 | M2: 설명
B3: ※ 자금현황 | G3: 기준일: 2023.05.31 | I3: USD | J3: =IFERROR(__xludf.DUMMYFUNCTION("GOOGLEFINANCE(""USDKRW"")"),1472.7250000000001) -> 1472.725 | L3: 광고매출 | M3: 타법인 매출
B4: 구 분 | C4: 단위 | D4: 전월잔액 | E4: 수 입 | F4: 지 출 | G4: 기준일 기준 잔액 | I4: SGD | J4: =IFERROR(__xludf.DUMMYFUNCTION("GOOGLEFINANCE(""SGDKRW"")"),1143.885) -> 1143.885 | L4: 급여 | M4: 직원 급여
B5: 신한 #672 | C5: KRW | D5: ='23.04월'!G5 -> 16701926 | E5: =sumif(B22:B180,B5,E22:E182) -> 34000000 | F5: =sumif(B22:B122,B5,F22:F122) -> 29151834 | G5: =D5+E5-F5 -> 21550092 | L5: 미수금 | M5: 돌려 받을 예정인 금액 (ex. 부가세 환급금)
B6: 신한 #543 | C6: USD | D6: ='23.04월'!G6 -> 2.31 | E6: =sumif(B22:B182,B6,E22:E182) -> 0 | F6: =sumif(B22:B122,B6,F22:F122) -> 0 | G6: =D6+E6-F6 -> 2.31 | L6: 보증금 | M6: 보증금 (사무실 임대, 장비 리스 등)
B7: 하나 #304 | C7: KRW | D7: ='23.04월'!G7 -> 45610896 | E7: =sumif(B22:B182,B7,E22:E182) -> 196646017 | F7: =sumif(B22:B122,B7,F22:F122) -> 221721127 | G7: =D7+E7-F7 -> 20535786 | L7: 보통예금 | M7: 예금간 이체
B8: 하나 #138 | C8: USD | D8: ='23.04월'!G8 -> 0.89 | E8: =sumif(B22:B182,B8,E22:E182) -> 149990 | F8: =sumif(B22:B122,B8,F22:F122) -> 149990.89 | G8: =D8+E8-F8 -> 0 | L8: 복리후생비 | M8: 회식, 식대
B9: WISE USD | C9: USD | D9: ='23.04월'!G9 -> 63773.59 | E9: =sumif(B22:B122,B9,E22:E182) -> 1995.86 | F9: =sumif(B22:B122,B9,F22:F122) -> 53684.89 | G9: =D9+E9-F9 -> 12084.56 | L9: 비품 | M9: 가구, 가전등 개당 단가 150만원이 넘는 용품
B10: WISE SGD | C10: SGD | D10: ='23.04월'!G10 -> 200 | E10: =sumif(B22:B180,B10,E22:E122) -> 10564 | F10: =sumif(B22:B122,B10,F22:F122) -> 10764 | G10: =D10+E10-F10 -> 0 | L10: 사무용품비 | M10: 비품, 소모품비를 제외한 업무용 사무용품 구입
B11: WISE KRW | C11: KRW | D11: ='23.04월'!G11 -> 0 | E11: =sumif(B22:B182,B11,E22:E182) -> 1569941 | F11: =sumif(B22:B122,B11,F22:F122) -> 1569941 | G11: =D11+E11-F11 -> 0 | L11: 서비스용역매출 | M11: 매출
B12: OCBC USD | C12: USD | D12: ='23.04월'!G12 -> 957089.27 | E12: =sumif(B25:B125,B12,E25:E183) -> 1000 | F12: =sumif(B22:B121,B12,F22:F121) -> 123196.42 | G12: =D12+E12-F12 -> 834892.85 | L12: 세금과공과 | M12: 세금 납부시
B13: OCBC SGD | C13: SGD | D13: ='23.04월'!G13 -> 780 | E13: =sumif(B22:B182,B13,E22:E122) -> 0 | F13: =sumif(B22:B121,B13,F22:F121) -> 25 | G13: =D13+E13-F13 -> 755 | L13: 소모품비 | M13: 비품(150만원)으로 잡기에는 금액이 작은 비품
L14: 여비교통비 | M14: 출장, 대중교통, 대리운전
B15: KRW 합 계 | D15: =D5+D7+D11 -> 62312822 | E15: =E5+E7+E11 -> 232215958 | F15: =F5+F7+F11 -> 252442902 | G15: =G5+G11+G7 -> 42085878 | H15: =G15 -> 42085878 | I15: =D15 -> 62312822 | L15: 용역비 | M15: 외주용역비
B16: USD 합 계 | D16: =D6+D8+D9+D12 -> 1020866.1 | E16: =E6+E8+E9+E12 -> 152985.86 | F16: =F6+F8+F9+F12 -> 326872.2 | G16: =G9+G6+G8+G12 -> 846979.72 | H16: =rounddown(G16*$J$3,0) -> 1247368208 | I16: =rounddown(D16*$J$3,0) -> 1503454968 | L16: 접대비 | M16: 외부 미팅
B17: SGD 합 계 | D17: =D10+D13 -> 980 | E17: =E10+E13 -> 10564 | F17: =F10+F13 -> 10789 | G17: =G10+G13 -> 755 | H17: =rounddown(G17*$J$4,0) -> 863633 | I17: =rounddown(D17*$J$4,0) -> 1121007 | L17: 지급수수료 | M17: sms 수수료, 송금 수수료, 일반적으로 발생되는 모든 비용
H18: =SUM(H15:H17) -> 1290317719 | I18: =SUM(I15:I17) -> 1566888797 | L18: 이자수익 | M18: 은행이자
L19: 통신비 | M19: 등기, 퀵 사용비
B20: ※ 세부내역 | L20: 마케팅비 | M20: PR 기사등 마케팅 비용
B21: 구 분 | C21: 날 짜 | D21: 은 행 적 요 | E21: 수입 | F21: 지출 | G21: 상세메모 | H21: 계정과목 | L21: 대여금 | M21: 싱가폴 -> 한국 지사 송금
B22: =B9 -> WISE USD | C22: 2023.05.01 | D22: Milestone Business Group | F22: 10422.68 | G22: Chris 5월 급여 | H22: 급여
B23: =B9 -> WISE USD | C23: 2023.05.01 | D23: wise | F23: 0.39 | G23: Chris 5월 급여 송금 수수료 | H23: 지급수수료
B24: =B7 -> 하나 #304 | C24: 2023.05.01 | D24: 강진석 | F24: 30000500 | G24: 대여금 | H24: 대여금
B25: =B7 -> 하나 #304 | C25: 2023.05.04 | D25: 드호스타일 | F25: 3842800 | G25: 행사 케이터링 서비스 | H25: 마케팅비
B26: =B7 -> 하나 #304 | C26: 2023.05.04 | D26: 그림바우빌딩 | F26: 6029820 | G26: 4월 임대료,관리비,전기료 | H26: 지급수수료
B27: =B7 -> 하나 #304 | C27: 2023.05.04 | D27: 비앤케이 | F27: 825500 | G27: 4월법률자문료 | H27: 지급수수료
B28: =B7 -> 하나 #304 | C28: 2023.05.04 | D28: 석진상회 | F28: 90500 | G28: 행사용 주류 구입 | H28: 마케팅비
B29: =B7 -> 하나 #304 | C29: 2023.05.04 | D29: 최고은 | F29: 40500 | G29: 워크샵 교통비 + 간식비 지원 (2명) | H29: 복리후생비
B30: =B7 -> 하나 #304 | C30: 2023.05.04 | D30: 최지현 | F30: 20500 | G30: 워크샵 교통비 + 간식비 지원 (1명) | H30: 복리후생비
B31: =B7 -> 하나 #304 | C31: 2023.05.04 | D31: 권우철 | F31: 20500 | G31: 워크샵 교통비 + 간식비 지원 (1명) | H31: 복리후생비
B32: =B7 -> 하나 #304 | C32: 2023.05.04 | D32: 이이슬 | F32: 100480 | G32: 개인경비 | H32: 복리후생비
B33: =B7 -> 하나 #304 | C33: 2023.05.08 | D33: 주식회사 제로엑스앤드 | F33: 4000500 | G33: 계좌간 자금 이체 | H33: 보통예금
B34: =B5 -> 신한 #672 | C34: 2023.05.08 | D34: 주식회사 제로엑스앤드 | E34: 4000000 | G34: 계좌간 자금 이체 | H34: 보통예금
B35: =B9 -> WISE USD | C35: 2023.05.08 | D35: ZERO X AND PTE. LTD | F35: 30014.39 | G35: 한국법인 운영비 | H35: 보통예금
B36: =B9 -> WISE USD | C36: 2023.05.08 | D36: Milestone Business Group | F36: =1735.02+0.39 -> 1735.41 | G36: Chris 개인경비 | H36: 복리후생비
B37: =B9 -> WISE USD | C37: 2023.05.08 | D37: ZERO X AND PTE. LTD | F37: 1200 | G37: 환전 | H37: 보통예금
B38: =B11 -> WISE KRW | C38: 2023.05.08 | D38: ZERO X AND PTE. LTD | E38: 1569941 | G38: 환전 | H38: 보통예금
B39: =B11 -> WISE KRW | C39: 2023.05.08 | D39: Jeon Juneyoung | F39: 1531450 | G39: 바트 개인경비 | H39: 복리후생비
B40: =B5 -> 신한 #672 | C40: 2023.05.10 | D40: 2304국민건강 | F40: 4894740 | G40: 2304국민건강 | H40: 세금과공과
...

Sheet 23.06월
B1: 자 금 일 보
I2: Currency | J2: KRW | L2: 계정과목 | M2: 설명
B3: ※ 자금현황 | G3: 기준일: 2023.06.26 | I3: USD | J3: =IFERROR(__xludf.DUMMYFUNCTION("GOOGLEFINANCE(""USDKRW"")"),1472.7250000000001) -> 1472.725 | L3: 광고매출 | M3: 타법인 매출
B4: 구 분 | C4: 단위 | D4: 전월잔액 | E4: 수 입 | F4: 지 출 | G4: 기준일 기준 잔액 | I4: SGD | J4: =IFERROR(__xludf.DUMMYFUNCTION("GOOGLEFINANCE(""SGDKRW"")"),1143.885) -> 1143.885 | L4: 급여 | M4: 직원 급여
B5: 신한 #672 | C5: KRW | D5: ='23.05월'!G5 -> 21550092 | E5: =sumif(B22:B184,B5,E22:E186) -> 30004999 | F5: =sumif(B22:B126,B5,F22:F187) -> 30841057 | G5: =D5+E5-F5 -> 20714034 | L5: 미수금 | M5: 돌려 받을 예정인 금액 (ex. 부가세 환급금)
B6: 신한 #543 | C6: USD | D6: ='23.05월'!G6 -> 2.31 | E6: =sumif(B22:B186,B6,E22:E186) -> 0 | F6: =sumif(B22:B126,B6,F22:F186) -> 0 | G6: =D6+E6-F6 -> 2.31 | L6: 보증금 | M6: 보증금 (사무실 임대, 장비 리스 등)
B7: 하나 #304 | C7: KRW | D7: ='23.05월'!G7 -> 20535786 | E7: =sumif(B22:B186,B7,E22:E186) -> 129556871 | F7: =sumif(B22:B126,B7,F22:F186) -> 146820392 | G7: =D7+E7-F7 -> 3272265 | L7: 보통예금 | M7: 예금간 이체
B8: 하나 #138 | C8: USD | D8: ='23.05월'!G8 -> 0 | E8: =sumif(B22:B186,B8,E22:E186) -> 100000.12 | F8: =sumif(B22:B126,B8,F22:F186) -> 100000 | G8: =D8+E8-F8 -> 0.12 | L8: 복리후생비 | M8: 회식, 식대
B9: WISE USD | C9: USD | D9: ='23.05월'!G9 -> 12084.56 | E9: =sumif(B22:B126,B9,E22:E186) -> 447995.98 | F9: =sumif(B22:B126,B9,F22:F186) -> 139469.69 | G9: =D9+E9-F9 -> 320610.85 | L9: 비품 | M9: 가구, 가전등 개당 단가 150만원이 넘는 용품
B10: WISE SGD | C10: SGD | D10: ='23.05월'!G10 -> 0 | E10: =sumif(B22:B184,B10,E22:E126) -> 0 | F10: =sumif(B22:B126,B10,F22:F186) -> 0 | G10: =D10+E10-F10 -> 0 | L10: 사무용품비 | M10: 비품, 소모품비를 제외한 업무용 사무용품 구입
B11: WISE KRW | C11: KRW | D11: ='23.05월'!G11 -> 0 | E11: =sumif(B22:B186,B11,E22:E186) -> 0 | F11: =sumif(B22:B126,B11,F22:F186) -> 0 | G11: =D11+E11-F11 -> 0 | L11: 서비스용역매출 | M11: 매출
B12: OCBC USD | C12: USD | D12: ='23.05월'!G12 -> 834892.85 | E12: =sumif(B22:B129,B12,E22:E129) -> 0 | F12: =sumif(B22:B125,B12,F22:F187) -> 448058.12 | G12: =D12+E12-F12 -> 386834.73 | L12: 세금과공과 | M12: 세금 납부시
B13: OCBC SGD | C13: SGD | D13: ='23.05월'!G13 -> 755 | E13: =sumif(B22:B186,B13,E22:E187) -> 0 | F13: =sumif(B22:B125,B13,F22:F187) -> 25 | G13: =D13+E13-F13 -> 730 | L13: 소모품비 | M13: 비품(150만원)으로 잡기에는 금액이 작은 비품
